Workbook
Name JO: [1]Impuls!$G$2:$G$56
Name KontoPrzychody: [1]Impuls!$AW$2:$AW$329
Name PKK: [1]Impuls!$K$2:$K$89
Name test: Raport!#REF!
Name test: Raport!#REF!
Name Zlecenie: [1]Impuls!$Q$2:$Q$278

Sheet Raport
M1: VER MAY 2026 | O1: 3 | P1: 4 | Q1: 5 | R1: 6 | S1: 7 | T1: 8 | U1: 9
E2: typ umowy: | G2: miesiąc:
E3: imię i nazwisko: | G3: rok: | I3: stawka za godzinę:
O4: NOWA DEKRETACJA
B5: Miesiąc | C5: Imię i Nazwisko | D5: Funkcja | E5: Data zakończenia | F5: Tytuł programu | G5: Opis | H5: Czynność | I5: Kwota | J5: Liczba godzin | L5: Sumy Pośrednie | M5: STARA Dekretacja | N5: Kod | O5: Właściciel budżetu | P5: Linia produktowa | Q5: Kategoria | R5: Podkategoria | S5: CC code | T5: CC name | U5: Artykuł
E6: DD-MM-RRRR | F6: - | G6: - | H6: - | I6: =SUM(I7:I63) -> 0 | J6: =SUM(J7:J63) -> 0 | L6: =SUM(L7:L104) -> 0 | M6: -
B7: =IF(F7="","",$M$2) | C7: =IF(F7="","",$F$3) | D7: =IF(F7="","",$M$3) | I7: =$J7*$J$3 -> 0 | L7: =IF(F7="","",IF(ISERROR(VLOOKUP(F7,F8:$F$500,1,0)),SUMIF(F:F,F7,I:I),"")) | M7: =IFERROR(VLOOKUP(F7,słownik!A:I,9,0),"") | N7: =IFERROR(VLOOKUP(M7,słownik!I:J,2,FALSE),"-") -> - | O7: =IFERROR(VLOOKUP($N7,słownik!$J$4:$AD$165,O$1,FALSE),"-") -> - | P7: =IFERROR(VLOOKUP($N7,słownik!$J$4:$AD$165,P$1,FALSE),"-") -> - | Q7: =IFERROR(VLOOKUP($N7,słownik!$J$4:$AD$165,Q$1,FALSE),"-") -> - | R7: =IFERROR(VLOOKUP($N7,słownik!$J$4:$AD$165,R$1,FALSE),"-") -> - | S7: =IFERROR(VLOOKUP($N7,słownik!$J$4:$AD$165,S$1,FALSE),"-") -> - | T7: =IFERROR(VLOOKUP($N7,słownik!$J$4:$AD$165,T$1,FALSE),"-") -> - | U7: =IFERROR(VLOOKUP($N7,słownik!$J$4:$AD$165,U$1,FALSE),"-") -> -
B8: =IF(F8="","",$M$2) | C8: =IF(F8="","",$F$3) | D8: =IF(F8="","",$M$3) | I8: =$J8*$J$3 -> 0 | L8: =IF(F8="","",IF(ISERROR(VLOOKUP(F8,F9:$F$500,1,0)),SUMIF(F:F,F8,I:I),"")) | M8: =IFERROR(VLOOKUP(F8,słownik!A:I,9,0),"") | N8: =IFERROR(VLOOKUP(M8,słownik!I:J,2,FALSE),"-") -> - | O8: =IFERROR(VLOOKUP($N8,słownik!$J$4:$AD$165,O$1,FALSE),"-") -> - | P8: =IFERROR(VLOOKUP($N8,słownik!$J$4:$AD$165,P$1,FALSE),"-") -> - | Q8: =IFERROR(VLOOKUP($N8,słownik!$J$4:$AD$165,Q$1,FALSE),"-") -> - | R8: =IFERROR(VLOOKUP($N8,słownik!$J$4:$AD$165,R$1,FALSE),"-") -> - | S8: =IFERROR(VLOOKUP($N8,słownik!$J$4:$AD$165,S$1,FALSE),"-") -> - | T8: =IFERROR(VLOOKUP($N8,słownik!$J$4:$AD$165,T$1,FALSE),"-") -> - | U8: =IFERROR(VLOOKUP($N8,słownik!$J$4:$AD$165,U$1,FALSE),"-") -> -
B9: =IF(F9="","",$M$2) | C9: =IF(F9="","",$F$3) | D9: =IF(F9="","",$M$3) | I9: =$J9*$J$3 -> 0 | L9: =IF(F9="","",IF(ISERROR(VLOOKUP(F9,F10:$F$500,1,0)),SUMIF(F:F,F9,I:I),"")) | M9: =IFERROR(VLOOKUP(F9,słownik!A:I,9,0),"") | N9: =IFERROR(VLOOKUP(M9,słownik!I:J,2,FALSE),"-") -> - | O9: =IFERROR(VLOOKUP($N9,słownik!$J$4:$AD$165,O$1,FALSE),"-") -> - | P9: =IFERROR(VLOOKUP($N9,słownik!$J$4:$AD$165,P$1,FALSE),"-") -> - | Q9: =IFERROR(VLOOKUP($N9,słownik!$J$4:$AD$165,Q$1,FALSE),"-") -> - | R9: =IFERROR(VLOOKUP($N9,słownik!$J$4:$AD$165,R$1,FALSE),"-") -> - | S9: =IFERROR(VLOOKUP($N9,słownik!$J$4:$AD$165,S$1,FALSE),"-") -> - | T9: =IFERROR(VLOOKUP($N9,słownik!$J$4:$AD$165,T$1,FALSE),"-") -> - | U9: =IFERROR(VLOOKUP($N9,słownik!$J$4:$AD$165,U$1,FALSE),"-") -> -
B10: =IF(F10="","",$M$2) | C10: =IF(F10="","",$F$3) | D10: =IF(F10="","",$M$3) | I10: =$J10*$J$3 -> 0 | L10: =IF(F10="","",IF(ISERROR(VLOOKUP(F10,F11:$F$500,1,0)),SUMIF(F:F,F10,I:I),"")) | M10: =IFERROR(VLOOKUP(F10,słownik!A:I,9,0),"") | N10: =IFERROR(VLOOKUP(M10,słownik!I:J,2,FALSE),"-") -> - | O10: =IFERROR(VLOOKUP($N10,słownik!$J$4:$AD$165,O$1,FALSE),"-") -> - | P10: =IFERROR(VLOOKUP($N10,słownik!$J$4:$AD$165,P$1,FALSE),"-") -> - | Q10: =IFERROR(VLOOKUP($N10,słownik!$J$4:$AD$165,Q$1,FALSE),"-") -> - | R10: =IFERROR(VLOOKUP($N10,słownik!$J$4:$AD$165,R$1,FALSE),"-") -> - | S10: =IFERROR(VLOOKUP($N10,słownik!$J$4:$AD$165,S$1,FALSE),"-") -> - | T10: =IFERROR(VLOOKUP($N10,słownik!$J$4:$AD$165,T$1,FALSE),"-") -> - | U10: =IFERROR(VLOOKUP($N10,słownik!$J$4:$AD$165,U$1,FALSE),"-") -> -
B11: =IF(F11="","",$M$2) | C11: =IF(F11="","",$F$3) | D11: =IF(F11="","",$M$3) | I11: =$J11*$J$3 -> 0 | L11: =IF(F11="","",IF(ISERROR(VLOOKUP(F11,F12:$F$500,1,0)),SUMIF(F:F,F11,I:I),"")) | M11: =IFERROR(VLOOKUP(F11,słownik!A:I,9,0),"") | N11: =IFERROR(VLOOKUP(M11,słownik!I:J,2,FALSE),"-") -> - | O11: =IFERROR(VLOOKUP($N11,słownik!$J$4:$AD$165,O$1,FALSE),"-") -> - | P11: =IFERROR(VLOOKUP($N11,słownik!$J$4:$AD$165,P$1,FALSE),"-") -> - | Q11: =IFERROR(VLOOKUP($N11,słownik!$J$4:$AD$165,Q$1,FALSE),"-") -> - | R11: =IFERROR(VLOOKUP($N11,słownik!$J$4:$AD$165,R$1,FALSE),"-") -> - | S11: =IFERROR(VLOOKUP($N11,słownik!$J$4:$AD$165,S$1,FALSE),"-") -> - | T11: =IFERROR(VLOOKUP($N11,słownik!$J$4:$AD$165,T$1,FALSE),"-") -> - | U11: =IFERROR(VLOOKUP($N11,słownik!$J$4:$AD$165,U$1,FALSE),"-") -> -
B12: =IF(F12="","",$M$2) | C12: =IF(F12="","",$F$3) | D12: =IF(F12="","",$M$3) | I12: =$J12*$J$3 -> 0 | L12: =IF(F12="","",IF(ISERROR(VLOOKUP(F12,F13:$F$500,1,0)),SUMIF(F:F,F12,I:I),"")) | M12: =IFERROR(VLOOKUP(F12,słownik!A:I,9,0),"") | N12: =IFERROR(VLOOKUP(M12,słownik!I:J,2,FALSE),"-") -> - | O12: =IFERROR(VLOOKUP($N12,słownik!$J$4:$AD$165,O$1,FALSE),"-") -> - | P12: =IFERROR(VLOOKUP($N12,słownik!$J$4:$AD$165,P$1,FALSE),"-") -> - | Q12: =IFERROR(VLOOKUP($N12,słownik!$J$4:$AD$165,Q$1,FALSE),"-") -> - | R12: =IFERROR(VLOOKUP($N12,słownik!$J$4:$AD$165,R$1,FALSE),"-") -> - | S12: =IFERROR(VLOOKUP($N12,słownik!$J$4:$AD$165,S$1,FALSE),"-") -> - | T12: =IFERROR(VLOOKUP($N12,słownik!$J$4:$AD$165,T$1,FALSE),"-") -> - | U12: =IFERROR(VLOOKUP($N12,słownik!$J$4:$AD$165,U$1,FALSE),"-") -> -
B13: =IF(F13="","",$M$2) | C13: =IF(F13="","",$F$3) | D13: =IF(F13="","",$M$3) | I13: =$J13*$J$3 -> 0 | L13: =IF(F13="","",IF(ISERROR(VLOOKUP(F13,F14:$F$500,1,0)),SUMIF(F:F,F13,I:I),"")) | M13: =IFERROR(VLOOKUP(F13,słownik!A:I,9,0),"") | N13: =IFERROR(VLOOKUP(M13,słownik!I:J,2,FALSE),"-") -> - | O13: =IFERROR(VLOOKUP($N13,słownik!$J$4:$AD$165,O$1,FALSE),"-") -> - | P13: =IFERROR(VLOOKUP($N13,słownik!$J$4:$AD$165,P$1,FALSE),"-") -> - | Q13: =IFERROR(VLOOKUP($N13,słownik!$J$4:$AD$165,Q$1,FALSE),"-") -> - | R13: =IFERROR(VLOOKUP($N13,słownik!$J$4:$AD$165,R$1,FALSE),"-") -> - | S13: =IFERROR(VLOOKUP($N13,słownik!$J$4:$AD$165,S$1,FALSE),"-") -> - | T13: =IFERROR(VLOOKUP($N13,słownik!$J$4:$AD$165,T$1,FALSE),"-") -> - | U13: =IFERROR(VLOOKUP($N13,słownik!$J$4:$AD$165,U$1,FALSE),"-") -> -
B14: =IF(F14="","",$M$2) | C14: =IF(F14="","",$F$3) | D14: =IF(F14="","",$M$3) | I14: =$J14*$J$3 -> 0 | L14: =IF(F14="","",IF(ISERROR(VLOOKUP(F14,F15:$F$500,1,0)),SUMIF(F:F,F14,I:I),"")) | M14: =IFERROR(VLOOKUP(F14,słownik!A:I,9,0),"") | N14: =IFERROR(VLOOKUP(M14,słownik!I:J,2,FALSE),"-") -> - | O14: =IFERROR(VLOOKUP($N14,słownik!$J$4:$AD$165,O$1,FALSE),"-") -> - | P14: =IFERROR(VLOOKUP($N14,słownik!$J$4:$AD$165,P$1,FALSE),"-") -> - | Q14: =IFERROR(VLOOKUP($N14,słownik!$J$4:$AD$165,Q$1,FALSE),"-") -> - | R14: =IFERROR(VLOOKUP($N14,słownik!$J$4:$AD$165,R$1,FALSE),"-") -> - | S14: =IFERROR(VLOOKUP($N14,słownik!$J$4:$AD$165,S$1,FALSE),"-") -> - | T14: =IFERROR(VLOOKUP($N14,słownik!$J$4:$AD$165,T$1,FALSE),"-") -> - | U14: =IFERROR(VLOOKUP($N14,słownik!$J$4:$AD$165,U$1,FALSE),"-") -> -
B15: =IF(F15="","",$M$2) | C15: =IF(F15="","",$F$3) | D15: =IF(F15="","",$M$3) | I15: =$J15*$J$3 -> 0 | L15: =IF(F15="","",IF(ISERROR(VLOOKUP(F15,F16:$F$500,1,0)),SUMIF(F:F,F15,I:I),"")) | M15: =IFERROR(VLOOKUP(F15,słownik!A:I,9,0),"") | N15: =IFERROR(VLOOKUP(M15,słownik!I:J,2,FALSE),"-") -> - | O15: =IFERROR(VLOOKUP($N15,słownik!$J$4:$AD$165,O$1,FALSE),"-") -> - | P15: =IFERROR(VLOOKUP($N15,słownik!$J$4:$AD$165,P$1,FALSE),"-") -> - | Q15: =IFERROR(VLOOKUP($N15,słownik!$J$4:$AD$165,Q$1,FALSE),"-") -> - | R15: =IFERROR(VLOOKUP($N15,słownik!$J$4:$AD$165,R$1,FALSE),"-") -> - | S15: =IFERROR(VLOOKUP($N15,słownik!$J$4:$AD$165,S$1,FALSE),"-") -> - | T15: =IFERROR(VLOOKUP($N15,słownik!$J$4:$AD$165,T$1,FALSE),"-") -> - | U15: =IFERROR(VLOOKUP($N15,słownik!$J$4:$AD$165,U$1,FALSE),"-") -> -
B16: =IF(F16="","",$M$2) | C16: =IF(F16="","",$F$3) | D16: =IF(F16="","",$M$3) | I16: =$J16*$J$3 -> 0 | L16: =IF(F16="","",IF(ISERROR(VLOOKUP(F16,F17:$F$500,1,0)),SUMIF(F:F,F16,I:I),"")) | M16: =IFERROR(VLOOKUP(F16,słownik!A:I,9,0),"") | N16: =IFERROR(VLOOKUP(M16,słownik!I:J,2,FALSE),"-") -> - | O16: =IFERROR(VLOOKUP($N16,słownik!$J$4:$AD$165,O$1,FALSE),"-") -> - | P16: =IFERROR(VLOOKUP($N16,słownik!$J$4:$AD$165,P$1,FALSE),"-") -> - | Q16: =IFERROR(VLOOKUP($N16,słownik!$J$4:$AD$165,Q$1,FALSE),"-") -> - | R16: =IFERROR(VLOOKUP($N16,słownik!$J$4:$AD$165,R$1,FALSE),"-") -> - | S16: =IFERROR(VLOOKUP($N16,słownik!$J$4:$AD$165,S$1,FALSE),"-") -> - | T16: =IFERROR(VLOOKUP($N16,słownik!$J$4:$AD$165,T$1,FALSE),"-") -> - | U16: =IFERROR(VLOOKUP($N16,słownik!$J$4:$AD$165,U$1,FALSE),"-") -> -
B17: =IF(F17="","",$M$2) | C17: =IF(F17="","",$F$3) | D17: =IF(F17="","",$M$3) | I17: =$J17*$J$3 -> 0 | L17: =IF(F17="","",IF(ISERROR(VLOOKUP(F17,F18:$F$500,1,0)),SUMIF(F:F,F17,I:I),"")) | M17: =IFERROR(VLOOKUP(F17,słownik!A:I,9,0),"") | N17: =IFERROR(VLOOKUP(M17,słownik!I:J,2,FALSE),"-") -> - | O17: =IFERROR(VLOOKUP($N17,słownik!$J$4:$AD$165,O$1,FALSE),"-") -> - | P17: =IFERROR(VLOOKUP($N17,słownik!$J$4:$AD$165,P$1,FALSE),"-") -> - | Q17: =IFERROR(VLOOKUP($N17,słownik!$J$4:$AD$165,Q$1,FALSE),"-") -> - | R17: =IFERROR(VLOOKUP($N17,słownik!$J$4:$AD$165,R$1,FALSE),"-") -> - | S17: =IFERROR(VLOOKUP($N17,słownik!$J$4:$AD$165,S$1,FALSE),"-") -> - | T17: =IFERROR(VLOOKUP($N17,słownik!$J$4:$AD$165,T$1,FALSE),"-") -> - | U17: =IFERROR(VLOOKUP($N17,słownik!$J$4:$AD$165,U$1,FALSE),"-") -> -
B18: =IF(F18="","",$M$2) | C18: =IF(F18="","",$F$3) | D18: =IF(F18="","",$M$3) | I18: =$J18*$J$3 -> 0 | L18: =IF(F18="","",IF(ISERROR(VLOOKUP(F18,F19:$F$500,1,0)),SUMIF(F:F,F18,I:I),"")) | M18: =IFERROR(VLOOKUP(F18,słownik!A:I,9,0),"") | N18: =IFERROR(VLOOKUP(M18,słownik!I:J,2,FALSE),"-") -> - | O18: =IFERROR(VLOOKUP($N18,słownik!$J$4:$AD$165,O$1,FALSE),"-") -> - | P18: =IFERROR(VLOOKUP($N18,słownik!$J$4:$AD$165,P$1,FALSE),"-") -> - | Q18: =IFERROR(VLOOKUP($N18,słownik!$J$4:$AD$165,Q$1,FALSE),"-") -> - | R18: =IFERROR(VLOOKUP($N18,słownik!$J$4:$AD$165,R$1,FALSE),"-") -> - | S18: =IFERROR(VLOOKUP($N18,słownik!$J$4:$AD$165,S$1,FALSE),"-") -> - | T18: =IFERROR(VLOOKUP($N18,słownik!$J$4:$AD$165,T$1,FALSE),"-") -> - | U18: =IFERROR(VLOOKUP($N18,słownik!$J$4:$AD$165,U$1,FALSE),"-") -> -
... B86: =IF(F86="","",$M$2) | C86: =IF(F86="","",$F$3) | D86: =IF(F86="","",$M$3) | I86: =$J86*$J$3 -> 0 | L86: =IF(F86="","",IF(ISERROR(VLOOKUP(F86,F87:$F$500,1,0)),SUMIF(F:F,F86,I:I),"")) | M86: =IFERROR(VLOOKUP(F86,słownik!A:I,9,0),"") | N86: =IFERROR(VLOOKUP(M86,słownik!I:J,2,FALSE),"-") -> - | O86: =IFERROR(VLOOKUP($N86,słownik!$J$4:$AD$165,O$1,FALSE),"-") -> - | P86: =IFERROR(VLOOKUP($N86,słownik!$J$4:$AD$165,P$1,FALSE),"-") -> - | Q86: =IFERROR(VLOOKUP($N86,słownik!$J$4:$AD$165,Q$1,FALSE),"-") -> - | R86: =IFERROR(VLOOKUP($N86,słownik!$J$4:$AD$165,R$1,FALSE),"-") -> - | S86: =IFERROR(VLOOKUP($N86,słownik!$J$4:$AD$165,S$1,FALSE),"-") -> - | T86: =IFERROR(VLOOKUP($N86,słownik!$J$4:$AD$165,T$1,FALSE),"-") -> - | U86: =IFERROR(VLOOKUP($N86,słownik!$J$4:$AD$165,U$1,FALSE),"-") -> -
B87: =IF(F87="","",$M$2) | C87: =IF(F87="","",$F$3) | D87: =IF(F87="","",$M$3) | L87: =IF(F87="","",IF(ISERROR(VLOOKUP(F87,F88:$F$500,1,0)),SUMIF(F:F,F87,I:I),"")) | M87: =IFERROR(VLOOKUP(F87,słownik!A:I,9,0),"") | N87: =IFERROR(VLOOKUP(M87,słownik!I:J,2,FALSE),"-") -> - | O87: =IFERROR(VLOOKUP($N87,słownik!$J$4:$AD$165,O$1,FALSE),"-") -> - | P87: =IFERROR(VLOOKUP($N87,słownik!$J$4:$AD$165,P$1,FALSE),"-") -> - | Q87: =IFERROR(VLOOKUP($N87,słownik!$J$4:$AD$165,Q$1,FALSE),"-") -> - | R87: =IFERROR(VLOOKUP($N87,słownik!$J$4:$AD$165,R$1,FALSE),"-") -> - | S87: =IFERROR(VLOOKUP($N87,słownik!$J$4:$AD$165,S$1,FALSE),"-") -> - | T87: =IFERROR(VLOOKUP($N87,słownik!$J$4:$AD$165,T$1,FALSE),"-") -> - | U87: =IFERROR(VLOOKUP($N87,słownik!$J$4:$AD$165,U$1,FALSE),"-") -> -
B88: =IF(F88="","",$M$2) | C88: =IF(F88="","",$F$3) | D88: =IF(F88="","",$M$3) | L88: =IF(F88="","",IF(ISERROR(VLOOKUP(F88,F89:$F$500,1,0)),SUMIF(F:F,F88,I:I),"")) | M88: =IFERROR(VLOOKUP(F88,słownik!A:I,9,0),"") | N88: =IFERROR(VLOOKUP(M88,słownik!I:J,2,FALSE),"-") -> - | O88: =IFERROR(VLOOKUP($N88,słownik!$J$4:$AD$165,O$1,FALSE),"-") -> - | P88: =IFERROR(VLOOKUP($N88,słownik!$J$4:$AD$165,P$1,FALSE),"-") -> - | Q88: =IFERROR(VLOOKUP($N88,słownik!$J$4:$AD$165,Q$1,FALSE),"-") -> - | R88: =IFERROR(VLOOKUP($N88,słownik!$J$4:$AD$165,R$1,FALSE),"-") -> - | S88: =IFERROR(VLOOKUP($N88,słownik!$J$4:$AD$165,S$1,FALSE),"-") -> - | T88: =IFERROR(VLOOKUP($N88,słownik!$J$4:$AD$165,T$1,FALSE),"-") -> - | U88: =IFERROR(VLOOKUP($N88,słownik!$J$4:$AD$165,U$1,FALSE),"-") -> -
B89: =IF(F89="","",$M$2) | C89: =IF(F89="","",$F$3) | D89: =IF(F89="","",$M$3) | L89: =IF(F89="","",IF(ISERROR(VLOOKUP(F89,F90:$F$500,1,0)),SUMIF(F:F,F89,I:I),"")) | M89: =IFERROR(VLOOKUP(F89,słownik!A:I,9,0),"") | N89: =IFERROR(VLOOKUP(M89,słownik!I:J,2,FALSE),"-") -> - | O89: =IFERROR(VLOOKUP($N89,słownik!$J$4:$AD$165,O$1,FALSE),"-") -> - | P89: =IFERROR(VLOOKUP($N89,słownik!$J$4:$AD$165,P$1,FALSE),"-") -> - | Q89: =IFERROR(VLOOKUP($N89,słownik!$J$4:$AD$165,Q$1,FALSE),"-") -> - | R89: =IFERROR(VLOOKUP($N89,słownik!$J$4:$AD$165,R$1,FALSE),"-") -> - | S89: =IFERROR(VLOOKUP($N89,słownik!$J$4:$AD$165,S$1,FALSE),"-") -> - | T89: =IFERROR(VLOOKUP($N89,słownik!$J$4:$AD$165,T$1,FALSE),"-") -> - | U89: =IFERROR(VLOOKUP($N89,słownik!$J$4:$AD$165,U$1,FALSE),"-") -> -
B90: =IF(F90="","",$M$2) | C90: =IF(F90="","",$F$3) | D90: =IF(F90="","",$M$3) | L90: =IF(F90="","",IF(ISERROR(VLOOKUP(F90,F91:$F$500,1,0)),SUMIF(F:F,F90,I:I),"")) | M90: =IFERROR(VLOOKUP(F90,słownik!A:I,9,0),"") | N90: =IFERROR(VLOOKUP(M90,słownik!I:J,2,FALSE),"-") -> - | O90: =IFERROR(VLOOKUP($N90,słownik!$J$4:$AD$165,O$1,FALSE),"-") -> - | P90: =IFERROR(VLOOKUP($N90,słownik!$J$4:$AD$165,P$1,FALSE),"-") -> - | Q90: =IFERROR(VLOOKUP($N90,słownik!$J$4:$AD$165,Q$1,FALSE),"-") -> - | R90: =IFERROR(VLOOKUP($N90,słownik!$J$4:$AD$165,R$1,FALSE),"-") -> - | S90: =IFERROR(VLOOKUP($N90,słownik!$J$4:$AD$165,S$1,FALSE),"-") -> - | T90: =IFERROR(VLOOKUP($N90,słownik!$J$4:$AD$165,T$1,FALSE),"-") -> - | U90: =IFERROR(VLOOKUP($N90,słownik!$J$4:$AD$165,U$1,FALSE),"-") -> -
B91: =IF(F91="","",$M$2) | C91: =IF(F91="","",$F$3) | D91: =IF(F91="","",$M$3) | L91: =IF(F91="","",IF(ISERROR(VLOOKUP(F91,F92:$F$500,1,0)),SUMIF(F:F,F91,I:I),"")) | M91: =IFERROR(VLOOKUP(F91,słownik!A:I,9,0),"") | N91: =IFERROR(VLOOKUP(M91,słownik!I:J,2,FALSE),"-") -> - | O91: =IFERROR(VLOOKUP($N91,słownik!$J$4:$AD$165,O$1,FALSE),"-") -> - | P91: =IFERROR(VLOOKUP($N91,słownik!$J$4:$AD$165,P$1,FALSE),"-") -> - | Q91: =IFERROR(VLOOKUP($N91,słownik!$J$4:$AD$165,Q$1,FALSE),"-") -> - | R91: =IFERROR(VLOOKUP($N91,słownik!$J$4:$AD$165,R$1,FALSE),"-") -> - | S91: =IFERROR(VLOOKUP($N91,słownik!$J$4:$AD$165,S$1,FALSE),"-") -> - | T91: =IFERROR(VLOOKUP($N91,słownik!$J$4:$AD$165,T$1,FALSE),"-") -> - | U91: =IFERROR(VLOOKUP($N91,słownik!$J$4:$AD$165,U$1,FALSE),"-") -> -
B92: =IF(F92="","",$M$2) | C92: =IF(F92="","",$F$3) | D92: =IF(F92="","",$M$3) | L92: =IF(F92="","",IF(ISERROR(VLOOKUP(F92,F93:$F$500,1,0)),SUMIF(F:F,F92,I:I),"")) | M92: =IFERROR(VLOOKUP(F92,słownik!A:I,9,0),"") | N92: =IFERROR(VLOOKUP(M92,słownik!I:J,2,FALSE),"-") -> - | O92: =IFERROR(VLOOKUP($N92,słownik!$J$4:$AD$165,O$1,FALSE),"-") -> - | P92: =IFERROR(VLOOKUP($N92,słownik!$J$4:$AD$165,P$1,FALSE),"-") -> - | Q92: =IFERROR(VLOOKUP($N92,słownik!$J$4:$AD$165,Q$1,FALSE),"-") -> - | R92: =IFERROR(VLOOKUP($N92,słownik!$J$4:$AD$165,R$1,FALSE),"-") -> - | S92: =IFERROR(VLOOKUP($N92,słownik!$J$4:$AD$165,S$1,FALSE),"-") -> - | T92: =IFERROR(VLOOKUP($N92,słownik!$J$4:$AD$165,T$1,FALSE),"-") -> - | U92: =IFERROR(VLOOKUP($N92,słownik!$J$4:$AD$165,U$1,FALSE),"-") -> -
B93: =IF(F93="","",$M$2) | C93: =IF(F93="","",$F$3) | D93: =IF(F93="","",$M$3) | L93: =IF(F93="","",IF(ISERROR(VLOOKUP(F93,F94:$F$500,1,0)),SUMIF(F:F,F93,I:I),"")) | M93: =IFERROR(VLOOKUP(F93,słownik!A:I,9,0),"") | N93: =IFERROR(VLOOKUP(M93,słownik!I:J,2,FALSE),"-") -> - | O93: =IFERROR(VLOOKUP($N93,słownik!$J$4:$AD$165,O$1,FALSE),"-") -> - | P93: =IFERROR(VLOOKUP($N93,słownik!$J$4:$AD$165,P$1,FALSE),"-") -> - | Q93: =IFERROR(VLOOKUP($N93,słownik!$J$4:$AD$165,Q$1,FALSE),"-") -> - | R93: =IFERROR(VLOOKUP($N93,słownik!$J$4:$AD$165,R$1,FALSE),"-") -> - | S93: =IFERROR(VLOOKUP($N93,słownik!$J$4:$AD$165,S$1,FALSE),"-") -> - | T93: =IFERROR(VLOOKUP($N93,słownik!$J$4:$AD$165,T$1,FALSE),"-") -> - | U93: =IFERROR(VLOOKUP($N93,słownik!$J$4:$AD$165,U$1,FALSE),"-") -> -
B94: =IF(F94="","",$M$2) | C94: =IF(F94="","",$F$3) | D94: =IF(F94="","",$M$3) | L94: =IF(F94="","",IF(ISERROR(VLOOKUP(F94,F95:$F$500,1,0)),SUMIF(F:F,F94,I:I),"")) | M94: =IFERROR(VLOOKUP(F94,słownik!A:I,9,0),"") | N94: =IFERROR(VLOOKUP(M94,słownik!I:J,2,FALSE),"-") -> - | O94: =IFERROR(VLOOKUP($N94,słownik!$J$4:$AD$165,O$1,FALSE),"-") -> - | P94: =IFERROR(VLOOKUP($N94,słownik!$J$4:$AD$165,P$1,FALSE),"-") -> - | Q94: =IFERROR(VLOOKUP($N94,słownik!$J$4:$AD$165,Q$1,FALSE),"-") -> - | R94: =IFERROR(VLOOKUP($N94,słownik!$J$4:$AD$165,R$1,FALSE),"-") -> - | S94: =IFERROR(VLOOKUP($N94,słownik!$J$4:$AD$165,S$1,FALSE),"-") -> - | T94: =IFERROR(VLOOKUP($N94,słownik!$J$4:$AD$165,T$1,FALSE),"-") -> - | U94: =IFERROR(VLOOKUP($N94,słownik!$J$4:$AD$165,U$1,FALSE),"-") -> -
B95: =IF(F95="","",$M$2) | C95: =IF(F95="","",$F$3) | D95: =IF(F95="","",$M$3) | L95: =IF(F95="","",IF(ISERROR(VLOOKUP(F95,F96:$F$500,1,0)),SUMIF(F:F,F95,I:I),"")) | M95: =IFERROR(VLOOKUP(F95,słownik!A:I,9,0),"") | N95: =IFERROR(VLOOKUP(M95,słownik!I:J,2,FALSE),"-") -> - | O95: =IFERROR(VLOOKUP($N95,słownik!$J$4:$AD$165,O$1,FALSE),"-") -> - | P95: =IFERROR(VLOOKUP($N95,słownik!$J$4:$AD$165,P$1,FALSE),"-") -> - | Q95: =IFERROR(VLOOKUP($N95,słownik!$J$4:$AD$165,Q$1,FALSE),"-") -> - | R95: =IFERROR(VLOOKUP($N95,słownik!$J$4:$AD$165,R$1,FALSE),"-") -> - | S95: =IFERROR(VLOOKUP($N95,słownik!$J$4:$AD$165,S$1,FALSE),"-") -> - | T95: =IFERROR(VLOOKUP($N95,słownik!$J$4:$AD$165,T$1,FALSE),"-") -> - | U95: =IFERROR(VLOOKUP($N95,słownik!$J$4:$AD$165,U$1,FALSE),"-") -> -
B96: =IF(F96="","",$M$2) | C96: =IF(F96="","",$F$3) | D96: =IF(F96="","",$M$3) | L96: =IF(F96="","",IF(ISERROR(VLOOKUP(F96,F97:$F$500,1,0)),SUMIF(F:F,F96,I:I),"")) | M96: =IFERROR(VLOOKUP(F96,słownik!A:I,9,0),"") | N96: =IFERROR(VLOOKUP(M96,słownik!I:J,2,FALSE),"-") -> - | O96: =IFERROR(VLOOKUP($N96,słownik!$J$4:$AD$165,O$1,FALSE),"-") -> - | P96: =IFERROR(VLOOKUP($N96,słownik!$J$4:$AD$165,P$1,FALSE),"-") -> - | Q96: =IFERROR(VLOOKUP($N96,słownik!$J$4:$AD$165,Q$1,FALSE),"-") -> - | R96: =IFERROR(VLOOKUP($N96,słownik!$J$4:$AD$165,R$1,FALSE),"-") -> - | S96: =IFERROR(VLOOKUP($N96,słownik!$J$4:$AD$165,S$1,FALSE),"-") -> - | T96: =IFERROR(VLOOKUP($N96,słownik!$J$4:$AD$165,T$1,FALSE),"-") -> - | U96: =IFERROR(VLOOKUP($N96,słownik!$J$4:$AD$165,U$1,FALSE),"-") -> -
B97: =IF(F97="","",$M$2) | C97: =IF(F97="","",$F$3) | D97: =IF(F97="","",$M$3) | L97: =IF(F97="","",IF(ISERROR(VLOOKUP(F97,F98:$F$500,1,0)),SUMIF(F:F,F97,I:I),"")) | M97: =IFERROR(VLOOKUP(F97,słownik!A:I,9,0),"") | N97: =IFERROR(VLOOKUP(M97,słownik!I:J,2,FALSE),"-") -> - | O97: =IFERROR(VLOOKUP($N97,słownik!$J$4:$AD$165,O$1,FALSE),"-") -> - | P97: =IFERROR(VLOOKUP($N97,słownik!$J$4:$AD$165,P$1,FALSE),"-") -> - | Q97: =IFERROR(VLOOKUP($N97,słownik!$J$4:$AD$165,Q$1,FALSE),"-") -> - | R97: =IFERROR(VLOOKUP($N97,słownik!$J$4:$AD$165,R$1,FALSE),"-") -> - | S97: =IFERROR(VLOOKUP($N97,słownik!$J$4:$AD$165,S$1,FALSE),"-") -> - | T97: =IFERROR(VLOOKUP($N97,słownik!$J$4:$AD$165,T$1,FALSE),"-") -> - | U97: =IFERROR(VLOOKUP($N97,słownik!$J$4:$AD$165,U$1,FALSE),"-") -> -
B98: =IF(F98="","",$M$2) | C98: =IF(F98="","",$F$3) | D98: =IF(F98="","",$M$3) | L98: =IF(F98="","",IF(ISERROR(VLOOKUP(F98,F99:$F$500,1,0)),SUMIF(F:F,F98,I:I),"")) | M98: =IFERROR(VLOOKUP(F98,słownik!A:I,9,0),"") | N98: =IFERROR(VLOOKUP(M98,słownik!I:J,2,FALSE),"-") -> - | O98: =IFERROR(VLOOKUP($N98,słownik!$J$4:$AD$165,O$1,FALSE),"-") -> - | P98: =IFERROR(VLOOKUP($N98,słownik!$J$4:$AD$165,P$1,FALSE),"-") -> - | Q98: =IFERROR(VLOOKUP($N98,słownik!$J$4:$AD$165,Q$1,FALSE),"-") -> - | R98: =IFERROR(VLOOKUP($N98,słownik!$J$4:$AD$165,R$1,FALSE),"-") -> - | S98: =IFERROR(VLOOKUP($N98,słownik!$J$4:$AD$165,S$1,FALSE),"-") -> - | T98: =IFERROR(VLOOKUP($N98,słownik!$J$4:$AD$165,T$1,FALSE),"-") -> - | U98: =IFERROR(VLOOKUP($N98,słownik!$J$4:$AD$165,U$1,FALSE),"-") -> -
... B404: =IF(F404="","",$M$2) | C404: =IF(F404="","",$F$3) | D404: =IF(F404="","",$M$3) | L404: =IF(F404="","",IF(ISERROR(VLOOKUP(F404,F405:$F$500,1,0)),SUMIF(F:F,F404,I:I),"")) | M404: =IFERROR(VLOOKUP(F404,słownik!A:I,9,0),"") | N404: =IFERROR(VLOOKUP(M404,słownik!I:J,2,FALSE),"-") -> - | O404: =IFERROR(VLOOKUP($N404,słownik!$J$4:$AD$165,O$1,FALSE),"-") -> - | P404: =IFERROR(VLOOKUP($N404,słownik!$J$4:$AD$165,P$1,FALSE),"-") -> - | Q404: =IFERROR(VLOOKUP($N404,słownik!$J$4:$AD$165,Q$1,FALSE),"-") -> - | R404: =IFERROR(VLOOKUP($N404,słownik!$J$4:$AD$165,R$1,FALSE),"-") -> - | S404: =IFERROR(VLOOKUP($N404,słownik!$J$4:$AD$165,S$1,FALSE),"-") -> - | T404: =IFERROR(VLOOKUP($N404,słownik!$J$4:$AD$165,T$1,FALSE),"-") -> - | U404: =IFERROR(VLOOKUP($N404,słownik!$J$4:$AD$165,U$1,FALSE),"-") -> -
B405: =IF(F405="","",$M$2) | C405: =IF(F405="","",$F$3) | D405: =IF(F405="","",$M$3)
B406: =IF(F406="","",$M$2) | C406: =IF(F406="","",$F$3) | D406: =IF(F406="","",$M$3)
B407: =IF(F407="","",$M$2) | C407: =IF(F407="","",$F$3) | D407: =IF(F407="","",$M$3)
B408: =IF(F408="","",$M$2) | C408: =IF(F408="","",$F$3) | D408: =IF(F408="","",$M$3)
B409: =IF(F409="","",$M$2) | C409: =IF(F409="","",$F$3) | D409: =IF(F409="","",$M$3)
B410: =IF(F410="","",$M$2) | C410: =IF(F410="","",$F$3) | D410: =IF(F410="","",$M$3)
B411: =IF(F411="","",$M$2) | C411: =IF(F411="","",$F$3) | D411: =IF(F411="","",$M$3)
B412: =IF(F412="","",$M$2) | C412: =IF(F412="","",$F$3) | D412: =IF(F412="","",$M$3)
...

Sheet słownik
L2: 14 | M2: 15 | N2: 16 | O2: 17 | P2: 18 | Q2: 19 | S2: 21 | T2: 22 | U2: 23 | V2: 24 | W2: 25 | X2: 26 | Y2: 27 | Z2: 28 | AA2: 29 | AB2: 30 | AC2: 31 | AD2: 32
A3: Program | B3: Dekretacja Axapta | C3: Indeks | D3: JO | E3: MPK | F3: PKK | G3: ZLEC | H3: KONTO | I3: NPK INDEKS | J3: KOD | K3: Konto_kod | L3: Właściciel budżetu | M3: Linia produktowa | N3: Kategoria | O3: Podkategoria | P3: CC code | Q3: CC name | R3: Artykuł | S3: Artykuł1 | T3: Artykuł2 | U3: Artykuł3 | V3: Artykuł4 | W3: Artykuł5 | X3: Artykuł6 | Y3: Artykuł7 | Z3: Artykuł8 | AA3: Artykuł9 | AB3: Artykuł10 | AC3: Artykuł11 | AD3: Artykuł12 | AF3: czy jest w schemacie
A4: 1na1 | B4: 5010000 D02 K13 RK637 AN00207 | C4: 5010000_D02_K13_RK637_AN00207 | D4: J32_CANAL+ SPORT | E4: M32_CANAL+ SPORT | F4: 4370_MAGAZINES | G4: Z3708_1 NA 1 / 1 NA 1 EXTRA | H4: 63202-1000_Koszty redakcji - umowy cywilno-prawne | I4: =LEFT(D4,3)&"_"&LEFT(E4,3)&"_"&LEFT(F4,4)&"_"&LEFT(G4,5)&"_"&LEFT(H4,10) -> J32_M32_4370_Z3708_63202-1000 | J4: =LEFT(D4,3)&"_"&LEFT(E4,3)&"_"&LEFT(F4,4)&"_"&LEFT(G4,5)&"_"&LEFT(H4,5) -> J32_M32_4370_Z3708_63202 | K4: =LEFT(H4,10) -> 63202-1000 | L4: =IFERROR(VLOOKUP($J4,[2]OPEX!$H:$AM,L$2,FALSE),"-") -> Sport Dep | M4: =IFERROR(VLOOKUP($J4,[2]OPEX!$H:$AM,M$2,FALSE),"-") -> C+Sport | N4: =IFERROR(VLOOKUP($J4,[2]OPEX!$H:$AM,N$2,FALSE),"-") -> Old Magazines | O4: =IFERROR(VLOOKUP($J4,[2]OPEX!$H:$AM,O$2,FALSE),"-") -> Pprod-Editing | P4: =IFERROR(VLOOKUP($J4,[2]OPEX!$H:$AM,P$2,FALSE),"-") -> PS1S0M0G13 | Q4: =IFERROR(VLOOKUP($J4,[2]OPEX!$H:$AM,Q$2,FALSE),"-") -> C+Sport Maga Old Postprod | R4: =S4 | S4: =IFERROR(VLOOKUP($J4,[2]OPEX!$H:$AM,S$2,FALSE),"-") | T4: =IFERROR(VLOOKUP($J4,[2]OPEX!$H:$AM,T$2,FALSE),"-") | U4: =IFERROR(VLOOKUP($J4,[2]OPEX!$H:$AM,U$2,FALSE),"-") | V4: =IFERROR(VLOOKUP($J4,[2]OPEX!$H:$AM,V$2,FALSE),"-") | W4: =IFERROR(VLOOKUP($J4,[2]OPEX!$H:$AM,W$2,FALSE),"-") | X4: =IFERROR(VLOOKUP($J4,[2]OPEX!$H:$AM,X$2,FALSE),"-") | Y4: =IFERROR(VLOOKUP($J4,[2]OPEX!$H:$AM,Y$2,FALSE),"-") | Z4: =IFERROR(VLOOKUP($J4,[2]OPEX!$H:$AM,Z$2,FALSE),"-") | ... AD4: =IFERROR(VLOOKUP($J4,[2]OPEX!$H:$AM,AD$2,FALSE),"-") | AF4: =VLOOKUP(J4,[3]BU_COSTS!$C:$C,1,FALSE) -> J32_M32_4370_Z3708_63202
A5: Boks Zagraniczny | B5: 5010000 D02 K13 RK504 AN00207 | C5: 5010000_D02_K13_RK504_AN00207 | D5: J32_CANAL+ SPORT | E5: M32_CANAL+ SPORT | F5: 4360_BOXING | G5: Z3651_FOREIGN BOXING | H5: 63202-1000_Koszty redakcji - umowy cywilno-prawne | I5: =LEFT(D5,3)&"_"&LEFT(E5,3)&"_"&LEFT(F5,4)&"_"&LEFT(G5,5)&"_"&LEFT(H5,10) -> J32_M32_4360_Z3651_63202-1000 | J5: =LEFT(D5,3)&"_"&LEFT(E5,3)&"_"&LEFT(F5,4)&"_"&LEFT(G5,5)&"_"&LEFT(H5,5) -> J32_M32_4360_Z3651_63202 | K5: =LEFT(H5,10) -> 63202-1000 | L5: =IFERROR(VLOOKUP($J5,[2]OPEX!$H:$AM,L$2,FALSE),"-") -> Sport Dep | M5: =IFERROR(VLOOKUP($J5,[2]OPEX!$H:$AM,M$2,FALSE),"-") -> C+Sport | N5: =IFERROR(VLOOKUP($J5,[2]OPEX!$H:$AM,N$2,FALSE),"-") -> Box | O5: =IFERROR(VLOOKUP($J5,[2]OPEX!$H:$AM,O$2,FALSE),"-") -> Pprod-Editing | P5: =IFERROR(VLOOKUP($J5,[2]OPEX!$H:$AM,P$2,FALSE),"-") -> PS1S0M04X3 | Q5: =IFERROR(VLOOKUP($J5,[2]OPEX!$H:$AM,Q$2,FALSE),"-") -> C+Sport Box Postprod | R5: =S5 -> PRODUKCJA – MONTAŻ/WIDEO/MIKS/AUDIO | S5: =IFERROR(VLOOKUP($J5,[2]OPEX!$H:$AM,S$2,FALSE),"-") -> PRODUKCJA – MONTAŻ/WIDEO/MIKS/AUDIO | T5: =IFERROR(VLOOKUP($J5,[2]OPEX!$H:$AM,T$2,FALSE),"-") | U5: =IFERROR(VLOOKUP($J5,[2]OPEX!$H:$AM,U$2,FALSE),"-") | V5: =IFERROR(VLOOKUP($J5,[2]OPEX!$H:$AM,V$2,FALSE),"-") | W5: =IFERROR(VLOOKUP($J5,[2]OPEX!$H:$AM,W$2,FALSE),"-") | X5: =IFERROR(VLOOKUP($J5,[2]OPEX!$H:$AM,X$2,FALSE),"-") | Y5: =IFERROR(VLOOKUP($J5,[2]OPEX!$H:$AM,Y$2,FALSE),"-") | Z5: =IFERROR(VLOOKUP($J5,[2]OPEX!$H:$AM,Z$2,FALSE),"-") | ... AD5: =IFERROR(VLOOKUP($J5,[2]OPEX!$H:$AM,AD$2,FALSE),"-") | AF5: =VLOOKUP(J5,[3]BU_COSTS!$C:$C,1,FALSE) -> J32_M32_4360_Z3651_63202
A6: BOXING WORLD WEEKLY | D6: J32_CANAL+ SPORT | E6: M32_CANAL+ SPORT | F6: 4370_MAGAZINES | G6: Z3725_WRC | H6: 63202-1000_Koszty redakcji - umowy cywilno-prawne | I6: =LEFT(D6,3)&"_"&LEFT(E6,3)&"_"&LEFT(F6,4)&"_"&LEFT(G6,5)&"_"&LEFT(H6,10) -> J32_M32_4370_Z3725_63202-1000 | J6: =LEFT(D6,3)&"_"&LEFT(E6,3)&"_"&LEFT(F6,4)&"_"&LEFT(G6,5)&"_"&LEFT(H6,5) -> J32_M32_4370_Z3725_63202 | K6: =LEFT(H6,10) -> 63202-1000 | L6: =IFERROR(VLOOKUP($J6,[2]OPEX!$H:$AM,L$2,FALSE),"-") -> Sport Dep | M6: =IFERROR(VLOOKUP($J6,[2]OPEX!$H:$AM,M$2,FALSE),"-") -> C+Sport | N6: =IFERROR(VLOOKUP($J6,[2]OPEX!$H:$AM,N$2,FALSE),"-") -> Martial Arts | O6: =IFERROR(VLOOKUP($J6,[2]OPEX!$H:$AM,O$2,FALSE),"-") -> Pprod-Editing | P6: =IFERROR(VLOOKUP($J6,[2]OPEX!$H:$AM,P$2,FALSE),"-") -> PS1S0M0UT3 | Q6: =IFERROR(VLOOKUP($J6,[2]OPEX!$H:$AM,Q$2,FALSE),"-") -> C+Sport Mag Martial Arts Postprod | R6: =S6 -> PRODUKCJA – MONTAŻ/WIDEO/MIKS/AUDIO | S6: =IFERROR(VLOOKUP($J6,[2]OPEX!$H:$AM,S$2,FALSE),"-") -> PRODUKCJA – MONTAŻ/WIDEO/MIKS/AUDIO | T6: =IFERROR(VLOOKUP($J6,[2]OPEX!$H:$AM,T$2,FALSE),"-") | U6: =IFERROR(VLOOKUP($J6,[2]OPEX!$H:$AM,U$2,FALSE),"-") | V6: =IFERROR(VLOOKUP($J6,[2]OPEX!$H:$AM,V$2,FALSE),"-") | W6: =IFERROR(VLOOKUP($J6,[2]OPEX!$H:$AM,W$2,FALSE),"-") | X6: =IFERROR(VLOOKUP($J6,[2]OPEX!$H:$AM,X$2,FALSE),"-") | Y6: =IFERROR(VLOOKUP($J6,[2]OPEX!$H:$AM,Y$2,FALSE),"-") | Z6: =IFERROR(VLOOKUP($J6,[2]OPEX!$H:$AM,Z$2,FALSE),"-") | ... AD6: =IFERROR(VLOOKUP($J6,[2]OPEX!$H:$AM,AD$2,FALSE),"-") | AF6: =VLOOKUP(J6,[3]BU_COSTS!$C:$C,1,FALSE) -> J32_M32_4370_Z3725_63202
A7: Ekstraklasa Po Godzinach | B7: 5010000 D02 K13 RK522 AN00207 | C7: 5010000_D02_K13_RK522_AN00207 | D7: J32_CANAL+ SPORT | E7: M32_CANAL+ SPORT | F7: 4370_MAGAZINES | G7: Z3722_EKSTRAKLASA PO GODZINACH | H7: 63202-1000_Koszty redakcji - umowy cywilno-prawne | I7: =LEFT(D7,3)&"_"&LEFT(E7,3)&"_"&LEFT(F7,4)&"_"&LEFT(G7,5)&"_"&LEFT(H7,10) -> J32_M32_4370_Z3722_63202-1000 | J7: =LEFT(D7,3)&"_"&LEFT(E7,3)&"_"&LEFT(F7,4)&"_"&LEFT(G7,5)&"_"&LEFT(H7,5) -> J32_M32_4370_Z3722_63202 | K7: =LEFT(H7,10) -> 63202-1000 | L7: =IFERROR(VLOOKUP($J7,[2]OPEX!$H:$AM,L$2,FALSE),"-") -> Sport Dep | M7: =IFERROR(VLOOKUP($J7,[2]OPEX!$H:$AM,M$2,FALSE),"-") -> C+Sport | N7: =IFERROR(VLOOKUP($J7,[2]OPEX!$H:$AM,N$2,FALSE),"-") -> EKL PG | O7: =IFERROR(VLOOKUP($J7,[2]OPEX!$H:$AM,O$2,FALSE),"-") -> Pprod-Editing | P7: =IFERROR(VLOOKUP($J7,[2]OPEX!$H:$AM,P$2,FALSE),"-") -> PS1S0M0CG3 | Q7: =IFERROR(VLOOKUP($J7,[2]OPEX!$H:$AM,Q$2,FALSE),"-") -> C+Sport Mag Ekstra PG Postprod | R7: =S7 -> PRODUKCJA – MONTAŻ/WIDEO/MIKS/AUDIO | S7: =IFERROR(VLOOKUP($J7,[2]OPEX!$H:$AM,S$2,FALSE),"-") -> PRODUKCJA – MONTAŻ/WIDEO/MIKS/AUDIO | T7: =IFERROR(VLOOKUP($J7,[2]OPEX!$H:$AM,T$2,FALSE),"-") | U7: =IFERROR(VLOOKUP($J7,[2]OPEX!$H:$AM,U$2,FALSE),"-") | V7: =IFERROR(VLOOKUP($J7,[2]OPEX!$H:$AM,V$2,FALSE),"-") | W7: =IFERROR(VLOOKUP($J7,[2]OPEX!$H:$AM,W$2,FALSE),"-") | X7: =IFERROR(VLOOKUP($J7,[2]OPEX!$H:$AM,X$2,FALSE),"-") | Y7: =IFERROR(VLOOKUP($J7,[2]OPEX!$H:$AM,Y$2,FALSE),"-") | Z7: =IFERROR(VLOOKUP($J7,[2]OPEX!$H:$AM,Z$2,FALSE),"-") | ... AD7: =IFERROR(VLOOKUP($J7,[2]OPEX!$H:$AM,AD$2,FALSE),"-") | AF7: =VLOOKUP(J7,[3]BU_COSTS!$C:$C,1,FALSE) -> J32_M32_4370_Z3722_63202
A8: Ekstraklasyka | D8: J32_CANAL+ SPORT | E8: M32_CANAL+ SPORT | F8: 4370_MAGAZINES | G8: Z3712_MAGAZYNY LIGA POLSKA | H8: 63202-1000_Koszty redakcji - umowy cywilno-prawne | I8: =LEFT(D8,3)&"_"&LEFT(E8,3)&"_"&LEFT(F8,4)&"_"&LEFT(G8,5)&"_"&LEFT(H8,10) -> J32_M32_4370_Z3712_63202-1000 | J8: =LEFT(D8,3)&"_"&LEFT(E8,3)&"_"&LEFT(F8,4)&"_"&LEFT(G8,5)&"_"&LEFT(H8,5) -> J32_M32_4370_Z3712_63202 | K8: =LEFT(H8,10) -> 63202-1000 | L8: =IFERROR(VLOOKUP($J8,[2]OPEX!$H:$AM,L$2,FALSE),"-") -> Sport Dep | M8: =IFERROR(VLOOKUP($J8,[2]OPEX!$H:$AM,M$2,FALSE),"-") -> C+Sport | N8: =IFERROR(VLOOKUP($J8,[2]OPEX!$H:$AM,N$2,FALSE),"-") -> Old Magazines | O8: =IFERROR(VLOOKUP($J8,[2]OPEX!$H:$AM,O$2,FALSE),"-") -> Production | P8: =IFERROR(VLOOKUP($J8,[2]OPEX!$H:$AM,P$2,FALSE),"-") -> PS1S0POL13 | Q8: =IFERROR(VLOOKUP($J8,[2]OPEX!$H:$AM,Q$2,FALSE),"-") -> C+Sport Magazines Old Production | R8: =S8 | S8: =IFERROR(VLOOKUP($J8,[2]OPEX!$H:$AM,S$2,FALSE),"-") | T8: =IFERROR(VLOOKUP($J8,[2]OPEX!$H:$AM,T$2,FALSE),"-") | U8: =IFERROR(VLOOKUP($J8,[2]OPEX!$H:$AM,U$2,FALSE),"-") | V8: =IFERROR(VLOOKUP($J8,[2]OPEX!$H:$AM,V$2,FALSE),"-") | W8: =IFERROR(VLOOKUP($J8,[2]OPEX!$H:$AM,W$2,FALSE),"-") | X8: =IFERROR(VLOOKUP($J8,[2]OPEX!$H:$AM,X$2,FALSE),"-") | Y8: =IFERROR(VLOOKUP($J8,[2]OPEX!$H:$AM,Y$2,FALSE),"-") | Z8: =IFERROR(VLOOKUP($J8,[2]OPEX!$H:$AM,Z$2,FALSE),"-") | ... AD8: =IFERROR(VLOOKUP($J8,[2]OPEX!$H:$AM,AD$2,FALSE),"-") | AF8: =VLOOKUP(J8,[3]BU_COSTS!$C:$C,1,FALSE) -> J32_M32_4370_Z3712_63202
A9: Gala Ekstraklasy | D9: J32_CANAL+ SPORT | E9: M32_CANAL+ SPORT | F9: 4356_SPECIAL EVENT | G9: Z3580_SPECIAL EVENTS | H9: 63202-1000_Koszty redakcji - umowy cywilno-prawne | I9: =LEFT(D9,3)&"_"&LEFT(E9,3)&"_"&LEFT(F9,4)&"_"&LEFT(G9,5)&"_"&LEFT(H9,10) -> J32_M32_4356_Z3580_63202-1000 | J9: =LEFT(D9,3)&"_"&LEFT(E9,3)&"_"&LEFT(F9,4)&"_"&LEFT(G9,5)&"_"&LEFT(H9,5) -> J32_M32_4356_Z3580_63202 | K9: =LEFT(H9,10) -> 63202-1000 | L9: =IFERROR(VLOOKUP($J9,[2]OPEX!$H:$AM,L$2,FALSE),"-") -> Sport Dep | M9: =IFERROR(VLOOKUP($J9,[2]OPEX!$H:$AM,M$2,FALSE),"-") -> C+Sport | N9: =IFERROR(VLOOKUP($J9,[2]OPEX!$H:$AM,N$2,FALSE),"-") -> Special Events | O9: =IFERROR(VLOOKUP($J9,[2]OPEX!$H:$AM,O$2,FALSE),"-") -> Pprod-Editing | P9: =IFERROR(VLOOKUP($J9,[2]OPEX!$H:$AM,P$2,FALSE),"-") -> PS1S0M15V3 | Q9: =IFERROR(VLOOKUP($J9,[2]OPEX!$H:$AM,Q$2,FALSE),"-") -> C+Sport Events Special Postprod | R9: =S9 -> PRODUKCJA – MONTAŻ/WIDEO/MIKS/AUDIO | S9: =IFERROR(VLOOKUP($J9,[2]OPEX!$H:$AM,S$2,FALSE),"-") -> PRODUKCJA – MONTAŻ/WIDEO/MIKS/AUDIO | T9: =IFERROR(VLOOKUP($J9,[2]OPEX!$H:$AM,T$2,FALSE),"-") | U9: =IFERROR(VLOOKUP($J9,[2]OPEX!$H:$AM,U$2,FALSE),"-") | V9: =IFERROR(VLOOKUP($J9,[2]OPEX!$H:$AM,V$2,FALSE),"-") | W9: =IFERROR(VLOOKUP($J9,[2]OPEX!$H:$AM,W$2,FALSE),"-") | X9: =IFERROR(VLOOKUP($J9,[2]OPEX!$H:$AM,X$2,FALSE),"-") | Y9: =IFERROR(VLOOKUP($J9,[2]OPEX!$H:$AM,Y$2,FALSE),"-") | Z9: =IFERROR(VLOOKUP($J9,[2]OPEX!$H:$AM,Z$2,FALSE),"-") | ... AD9: =IFERROR(VLOOKUP($J9,[2]OPEX!$H:$AM,AD$2,FALSE),"-") | AF9: =VLOOKUP(J9,[3]BU_COSTS!$C:$C,1,FALSE) -> J32_M32_4356_Z3580_63202
A10: Gala Ekstraligi | D10: J32_CANAL+ SPORT | E10: M32_CANAL+ SPORT | F10: 4356_SPECIAL EVENT | G10: Z3580_SPECIAL EVENTS | H10: 63202-1000_Koszty redakcji - umowy cywilno-prawne | I10: =LEFT(D10,3)&"_"&LEFT(E10,3)&"_"&LEFT(F10,4)&"_"&LEFT(G10,5)&"_"&LEFT(H10,10) -> J32_M32_4356_Z3580_63202-1000 | J10: =LEFT(D10,3)&"_"&LEFT(E10,3)&"_"&LEFT(F10,4)&"_"&LEFT(G10,5)&"_"&LEFT(H10,5) -> J32_M32_4356_Z3580_63202 | K10: =LEFT(H10,10) -> 63202-1000 | L10: =IFERROR(VLOOKUP($J10,[2]OPEX!$H:$AM,L$2,FALSE),"-") -> Sport Dep | M10: =IFERROR(VLOOKUP($J10,[2]OPEX!$H:$AM,M$2,FALSE),"-") -> C+Sport | N10: =IFERROR(VLOOKUP($J10,[2]OPEX!$H:$AM,N$2,FALSE),"-") -> Special Events | O10: =IFERROR(VLOOKUP($J10,[2]OPEX!$H:$AM,O$2,FALSE),"-") -> Pprod-Editing | P10: =IFERROR(VLOOKUP($J10,[2]OPEX!$H:$AM,P$2,FALSE),"-") -> PS1S0M15V3 | Q10: =IFERROR(VLOOKUP($J10,[2]OPEX!$H:$AM,Q$2,FALSE),"-") -> C+Sport Events Special Postprod | R10: =S10 -> PRODUKCJA – MONTAŻ/WIDEO/MIKS/AUDIO | S10: =IFERROR(VLOOKUP($J10,[2]OPEX!$H:$AM,S$2,FALSE),"-") -> PRODUKCJA – MONTAŻ/WIDEO/MIKS/AUDIO | T10: =IFERROR(VLOOKUP($J10,[2]OPEX!$H:$AM,T$2,FALSE),"-") | U10: =IFERROR(VLOOKUP($J10,[2]OPEX!$H:$AM,U$2,FALSE),"-") | V10: =IFERROR(VLOOKUP($J10,[2]OPEX!$H:$AM,V$2,FALSE),"-") | W10: =IFERROR(VLOOKUP($J10,[2]OPEX!$H:$AM,W$2,FALSE),"-") | X10: =IFERROR(VLOOKUP($J10,[2]OPEX!$H:$AM,X$2,FALSE),"-") | Y10: =IFERROR(VLOOKUP($J10,[2]OPEX!$H:$AM,Y$2,FALSE),"-") | Z10: =IFERROR(VLOOKUP($J10,[2]OPEX!$H:$AM,Z$2,FALSE),"-") | ... AD10: =IFERROR(VLOOKUP($J10,[2]OPEX!$H:$AM,AD$2,FALSE),"-") | AF10: =VLOOKUP(J10,[3]BU_COSTS!$C:$C,1,FALSE) -> J32_M32_4356_Z3580_63202
A11: GALE BKFC | D11: J32_CANAL+ SPORT | E11: M32_CANAL+ SPORT | F11: 4370_MAGAZINES | G11: Z3725_WRC | H11: 63202-1000_Koszty redakcji - umowy cywilno-prawne | I11: =LEFT(D11,3)&"_"&LEFT(E11,3)&"_"&LEFT(F11,4)&"_"&LEFT(G11,5)&"_"&LEFT(H11,10) -> J32_M32_4370_Z3725_63202-1000 | J11: =LEFT(D11,3)&"_"&LEFT(E11,3)&"_"&LEFT(F11,4)&"_"&LEFT(G11,5)&"_"&LEFT(H11,5) -> J32_M32_4370_Z3725_63202 | K11: =LEFT(H11,10) -> 63202-1000 | L11: =IFERROR(VLOOKUP($J11,[2]OPEX!$H:$AM,L$2,FALSE),"-") -> Sport Dep | M11: =IFERROR(VLOOKUP($J11,[2]OPEX!$H:$AM,M$2,FALSE),"-") -> C+Sport | N11: =IFERROR(VLOOKUP($J11,[2]OPEX!$H:$AM,N$2,FALSE),"-") -> Martial Arts | O11: =IFERROR(VLOOKUP($J11,[2]OPEX!$H:$AM,O$2,FALSE),"-") -> Pprod-Editing | P11: =IFERROR(VLOOKUP($J11,[2]OPEX!$H:$AM,P$2,FALSE),"-") -> PS1S0M0UT3 | Q11: =IFERROR(VLOOKUP($J11,[2]OPEX!$H:$AM,Q$2,FALSE),"-") -> C+Sport Mag Martial Arts Postprod | R11: =S11 -> PRODUKCJA – MONTAŻ/WIDEO/MIKS/AUDIO | S11: =IFERROR(VLOOKUP($J11,[2]OPEX!$H:$AM,S$2,FALSE),"-") -> PRODUKCJA – MONTAŻ/WIDEO/MIKS/AUDIO | T11: =IFERROR(VLOOKUP($J11,[2]OPEX!$H:$AM,T$2,FALSE),"-") | U11: =IFERROR(VLOOKUP($J11,[2]OPEX!$H:$AM,U$2,FALSE),"-") | V11: =IFERROR(VLOOKUP($J11,[2]OPEX!$H:$AM,V$2,FALSE),"-") | W11: =IFERROR(VLOOKUP($J11,[2]OPEX!$H:$AM,W$2,FALSE),"-") | X11: =IFERROR(VLOOKUP($J11,[2]OPEX!$H:$AM,X$2,FALSE),"-") | Y11: =IFERROR(VLOOKUP($J11,[2]OPEX!$H:$AM,Y$2,FALSE),"-") | Z11: =IFERROR(VLOOKUP($J11,[2]OPEX!$H:$AM,Z$2,FALSE),"-") | ... AD11: =IFERROR(VLOOKUP($J11,[2]OPEX!$H:$AM,AD$2,FALSE),"-") | AF11: =VLOOKUP(J11,[3]BU_COSTS!$C:$C,1,FALSE) -> J32_M32_4370_Z3725_63202
A12: Jej Wysokość Premier League | C12: 5010000_D02_K13_RK511_AN00207 | D12: J32_CANAL+ SPORT | E12: M32_CANAL+ SPORT | F12: 4370_MAGAZINES | G12: Z3711_JW PREMIER LEAGUE | H12: 63202-1000_Koszty redakcji - umowy cywilno-prawne | I12: =LEFT(D12,3)&"_"&LEFT(E12,3)&"_"&LEFT(F12,4)&"_"&LEFT(G12,5)&"_"&LEFT(H12,10) -> J32_M32_4370_Z3711_63202-1000 | J12: =LEFT(D12,3)&"_"&LEFT(E12,3)&"_"&LEFT(F12,4)&"_"&LEFT(G12,5)&"_"&LEFT(H12,5) -> J32_M32_4370_Z3711_63202 | K12: =LEFT(H12,10) -> 63202-1000 | L12: =IFERROR(VLOOKUP($J12,[2]OPEX!$H:$AM,L$2,FALSE),"-") -> Sport Dep | M12: =IFERROR(VLOOKUP($J12,[2]OPEX!$H:$AM,M$2,FALSE),"-") -> C+Sport | N12: =IFERROR(VLOOKUP($J12,[2]OPEX!$H:$AM,N$2,FALSE),"-") -> JWPL | O12: =IFERROR(VLOOKUP($J12,[2]OPEX!$H:$AM,O$2,FALSE),"-") -> Pprod-Editing | P12: =IFERROR(VLOOKUP($J12,[2]OPEX!$H:$AM,P$2,FALSE),"-") -> PS1S0M0HP3 | Q12: =IFERROR(VLOOKUP($J12,[2]OPEX!$H:$AM,Q$2,FALSE),"-") -> C+Sport Mag JWPL Postprod | R12: =S12 -> PRODUKCJA – MONTAŻ/WIDEO/MIKS/AUDIO | S12: =IFERROR(VLOOKUP($J12,[2]OPEX!$H:$AM,S$2,FALSE),"-") -> PRODUKCJA – MONTAŻ/WIDEO/MIKS/AUDIO | T12: =IFERROR(VLOOKUP($J12,[2]OPEX!$H:$AM,T$2,FALSE),"-") | U12: =IFERROR(VLOOKUP($J12,[2]OPEX!$H:$AM,U$2,FALSE),"-") | V12: =IFERROR(VLOOKUP($J12,[2]OPEX!$H:$AM,V$2,FALSE),"-") | W12: =IFERROR(VLOOKUP($J12,[2]OPEX!$H:$AM,W$2,FALSE),"-") | X12: =IFERROR(VLOOKUP($J12,[2]OPEX!$H:$AM,X$2,FALSE),"-") | Y12: =IFERROR(VLOOKUP($J12,[2]OPEX!$H:$AM,Y$2,FALSE),"-") | Z12: =IFERROR(VLOOKUP($J12,[2]OPEX!$H:$AM,Z$2,FALSE),"-") | ... AD12: =IFERROR(VLOOKUP($J12,[2]OPEX!$H:$AM,AD$2,FALSE),"-") | AF12: =VLOOKUP(J12,[3]BU_COSTS!$C:$C,1,FALSE) -> J32_M32_4370_Z3711_63202
A13: Liga Angielska - EPL | D13: J32_CANAL+ SPORT | E13: M32_CANAL+ SPORT | F13: 4357_FOOTBALL | G13: Z3606_ENGLISH LEAGUE | H13: 63202-1000_Koszty redakcji - umowy cywilno-prawne | I13: =LEFT(D13,3)&"_"&LEFT(E13,3)&"_"&LEFT(F13,4)&"_"&LEFT(G13,5)&"_"&LEFT(H13,10) -> J32_M32_4357_Z3606_63202-1000 | J13: =LEFT(D13,3)&"_"&LEFT(E13,3)&"_"&LEFT(F13,4)&"_"&LEFT(G13,5)&"_"&LEFT(H13,5) -> J32_M32_4357_Z3606_63202 | K13: =LEFT(H13,10) -> 63202-1000 | L13: =IFERROR(VLOOKUP($J13,[2]OPEX!$H:$AM,L$2,FALSE),"-") -> Sport Dep | M13: =IFERROR(VLOOKUP($J13,[2]OPEX!$H:$AM,M$2,FALSE),"-") -> C+Sport | N13: =IFERROR(VLOOKUP($J13,[2]OPEX!$H:$AM,N$2,FALSE),"-") -> EPL | O13: =IFERROR(VLOOKUP($J13,[2]OPEX!$H:$AM,O$2,FALSE),"-") -> Pprod-Editing | P13: =IFERROR(VLOOKUP($J13,[2]OPEX!$H:$AM,P$2,FALSE),"-") -> PS1S0M08L3 | Q13: =IFERROR(VLOOKUP($J13,[2]OPEX!$H:$AM,Q$2,FALSE),"-") -> C+Sport Football EPL Postprod | R13: =S13 -> PRODUKCJA – MONTAŻ/WIDEO/MIKS/AUDIO | S13: =IFERROR(VLOOKUP($J13,[2]OPEX!$H:$AM,S$2,FALSE),"-") -> PRODUKCJA – MONTAŻ/WIDEO/MIKS/AUDIO | T13: =IFERROR(VLOOKUP($J13,[2]OPEX!$H:$AM,T$2,FALSE),"-") | U13: =IFERROR(VLOOKUP($J13,[2]OPEX!$H:$AM,U$2,FALSE),"-") | V13: =IFERROR(VLOOKUP($J13,[2]OPEX!$H:$AM,V$2,FALSE),"-") | W13: =IFERROR(VLOOKUP($J13,[2]OPEX!$H:$AM,W$2,FALSE),"-") | X13: =IFERROR(VLOOKUP($J13,[2]OPEX!$H:$AM,X$2,FALSE),"-") | Y13: =IFERROR(VLOOKUP($J13,[2]OPEX!$H:$AM,Y$2,FALSE),"-") | Z13: =IFERROR(VLOOKUP($J13,[2]OPEX!$H:$AM,Z$2,FALSE),"-") | ... AD13: =IFERROR(VLOOKUP($J13,[2]OPEX!$H:$AM,AD$2,FALSE),"-") | AF13: =VLOOKUP(J13,[3]BU_COSTS!$C:$C,1,FALSE) -> J32_M32_4357_Z3606_63202
A14: Liga Angielska CZECHY | D14: J32_CANAL+ SPORT | E14: M02_EXTERNAL MARKETS | F14: 4374_PROJECT EPL/M7 | G14: Z3606_ENGLISH LEAGUE | H14: 63202-1000_Koszty redakcji - umowy cywilno-prawne | I14: =LEFT(D14,3)&"_"&LEFT(E14,3)&"_"&LEFT(F14,4)&"_"&LEFT(G14,5)&"_"&LEFT(H14,10) -> J32_M02_4374_Z3606_63202-1000 | J14: =LEFT(D14,3)&"_"&LEFT(E14,3)&"_"&LEFT(F14,4)&"_"&LEFT(G14,5)&"_"&LEFT(H14,5) -> J32_M02_4374_Z3606_63202 | K14: =LEFT(H14,10) -> 63202-1000 | L14: Sport Dep | M14: Group Services | N14: M7/EPL | O14: Production | P14: PS1X0PPL73 | Q14: Export Services EPL/M7 Production | R14: PRACOWNICY TYMCZASOWI | S14: PODRÓŻE – ZAKUP BILETÓW | T14: PRACOWNICY TYMCZASOWI | U14: PRODUKCJA – INNE USŁUGI AUDIOWIZUALNE | V14: USŁUGI PRODUKCYJNE ZEWNĘTRZNE | W14: =IFERROR(VLOOKUP($J14,[2]OPEX!$H:$AM,W$2,FALSE),"-") -> - | X14: =IFERROR(VLOOKUP($J14,[2]OPEX!$H:$AM,X$2,FALSE),"-") -> - | Y14: =IFERROR(VLOOKUP($J14,[2]OPEX!$H:$AM,Y$2,FALSE),"-") -> - | Z14: =IFERROR(VLOOKUP($J14,[2]OPEX!$H:$AM,Z$2,FALSE),"-") -> - | AA14: =IFERROR(VLOOKUP($J14,[2]OPEX!$H:$AM,AA$2,FALSE),"-") -> - | AB14: =IFERROR(VLOOKUP($J14,[2]OPEX!$H:$AM,AB$2,FALSE),"-") -> - | AC14: =IFERROR(VLOOKUP($J14,[2]OPEX!$H:$AM,AC$2,FALSE),"-") -> - | AD14: =IFERROR(VLOOKUP($J14,[2]OPEX!$H:$AM,AD$2,FALSE),"-") -> - | AF14: =VLOOKUP(J14,[3]BU_COSTS!$C:$C,1,FALSE) -> #N/A
A15: Liga Hiszpańska La Liga | D15: J32_CANAL+ SPORT | E15: M32_CANAL+ SPORT | F15: 4357_FOOTBALL | G15: Z3603_SPANISH LEAGUE | H15: 63202-1000_Koszty redakcji - umowy cywilno-prawne | I15: =LEFT(D15,3)&"_"&LEFT(E15,3)&"_"&LEFT(F15,4)&"_"&LEFT(G15,5)&"_"&LEFT(H15,10) -> J32_M32_4357_Z3603_63202-1000 | J15: =LEFT(D15,3)&"_"&LEFT(E15,3)&"_"&LEFT(F15,4)&"_"&LEFT(G15,5)&"_"&LEFT(H15,5) -> J32_M32_4357_Z3603_63202 | K15: =LEFT(H15,10) -> 63202-1000 | L15: =IFERROR(VLOOKUP($J15,[2]OPEX!$H:$AM,L$2,FALSE),"-") -> Sport Dep | M15: =IFERROR(VLOOKUP($J15,[2]OPEX!$H:$AM,M$2,FALSE),"-") -> C+Sport | N15: =IFERROR(VLOOKUP($J15,[2]OPEX!$H:$AM,N$2,FALSE),"-") -> La Liga | O15: =IFERROR(VLOOKUP($J15,[2]OPEX!$H:$AM,O$2,FALSE),"-") -> Pprod-Editing | P15: =IFERROR(VLOOKUP($J15,[2]OPEX!$H:$AM,P$2,FALSE),"-") -> PS1S0M0AL3 | Q15: =IFERROR(VLOOKUP($J15,[2]OPEX!$H:$AM,Q$2,FALSE),"-") -> C+Sport Football La Liga Postprod | R15: =S15 -> PRODUKCJA – MONTAŻ/WIDEO/MIKS/AUDIO | S15: =IFERROR(VLOOKUP($J15,[2]OPEX!$H:$AM,S$2,FALSE),"-") -> PRODUKCJA – MONTAŻ/WIDEO/MIKS/AUDIO | T15: =IFERROR(VLOOKUP($J15,[2]OPEX!$H:$AM,T$2,FALSE),"-") | U15: =IFERROR(VLOOKUP($J15,[2]OPEX!$H:$AM,U$2,FALSE),"-") | V15: =IFERROR(VLOOKUP($J15,[2]OPEX!$H:$AM,V$2,FALSE),"-") | W15: =IFERROR(VLOOKUP($J15,[2]OPEX!$H:$AM,W$2,FALSE),"-") | X15: =IFERROR(VLOOKUP($J15,[2]OPEX!$H:$AM,X$2,FALSE),"-") | Y15: =IFERROR(VLOOKUP($J15,[2]OPEX!$H:$AM,Y$2,FALSE),"-") | Z15: =IFERROR(VLOOKUP($J15,[2]OPEX!$H:$AM,Z$2,FALSE),"-") | ... AD15: =IFERROR(VLOOKUP($J15,[2]OPEX!$H:$AM,AD$2,FALSE),"-") | AF15: =VLOOKUP(J15,[3]BU_COSTS!$C:$C,1,FALSE) -> J32_M32_4357_Z3603_63202
A16: Liga Polska - Ekstraklasa | D16: J32_CANAL+ SPORT | E16: M32_CANAL+ SPORT | F16: 4357_FOOTBALL | G16: Z3601_POLISH LEAGUE | H16: 63202-1000_Koszty redakcji - umowy cywilno-prawne | I16: =LEFT(D16,3)&"_"&LEFT(E16,3)&"_"&LEFT(F16,4)&"_"&LEFT(G16,5)&"_"&LEFT(H16,10) -> J32_M32_4357_Z3601_63202-1000 | J16: =LEFT(D16,3)&"_"&LEFT(E16,3)&"_"&LEFT(F16,4)&"_"&LEFT(G16,5)&"_"&LEFT(H16,5) -> J32_M32_4357_Z3601_63202 | K16: =LEFT(H16,10) -> 63202-1000 | L16: =IFERROR(VLOOKUP($J16,[2]OPEX!$H:$AM,L$2,FALSE),"-") -> Sport Dep | M16: =IFERROR(VLOOKUP($J16,[2]OPEX!$H:$AM,M$2,FALSE),"-") -> C+Sport | N16: =IFERROR(VLOOKUP($J16,[2]OPEX!$H:$AM,N$2,FALSE),"-") -> Ekstraklasa | O16: =IFERROR(VLOOKUP($J16,[2]OPEX!$H:$AM,O$2,FALSE),"-") -> Pprod-Editing | P16: =IFERROR(VLOOKUP($J16,[2]OPEX!$H:$AM,P$2,FALSE),"-") -> PS1S0M09L3 | Q16: =IFERROR(VLOOKUP($J16,[2]OPEX!$H:$AM,Q$2,FALSE),"-") -> C+Sport Football Ekstraklasa Postprod | R16: =S16 -> PRODUKCJA – MONTAŻ/WIDEO/MIKS/AUDIO | S16: =IFERROR(VLOOKUP($J16,[2]OPEX!$H:$AM,S$2,FALSE),"-") -> PRODUKCJA – MONTAŻ/WIDEO/MIKS/AUDIO | T16: =IFERROR(VLOOKUP($J16,[2]OPEX!$H:$AM,T$2,FALSE),"-") | U16: =IFERROR(VLOOKUP($J16,[2]OPEX!$H:$AM,U$2,FALSE),"-") | V16: =IFERROR(VLOOKUP($J16,[2]OPEX!$H:$AM,V$2,FALSE),"-") | W16: =IFERROR(VLOOKUP($J16,[2]OPEX!$H:$AM,W$2,FALSE),"-") | X16: =IFERROR(VLOOKUP($J16,[2]OPEX!$H:$AM,X$2,FALSE),"-") | Y16: =IFERROR(VLOOKUP($J16,[2]OPEX!$H:$AM,Y$2,FALSE),"-") | Z16: =IFERROR(VLOOKUP($J16,[2]OPEX!$H:$AM,Z$2,FALSE),"-") | ... AD16: =IFERROR(VLOOKUP($J16,[2]OPEX!$H:$AM,AD$2,FALSE),"-") | AF16: =VLOOKUP(J16,[3]BU_COSTS!$C:$C,1,FALSE) -> J32_M32_4357_Z3601_63202
A17: Liga+ | D17: J32_CANAL+ SPORT | E17: M32_CANAL+ SPORT | F17: 4370_MAGAZINES | G17: Z3703_LIGA+ | H17: 63202-1000_Koszty redakcji - umowy cywilno-prawne | I17: =LEFT(D17,3)&"_"&LEFT(E17,3)&"_"&LEFT(F17,4)&"_"&LEFT(G17,5)&"_"&LEFT(H17,10) -> J32_M32_4370_Z3703_63202-1000 | J17: =LEFT(D17,3)&"_"&LEFT(E17,3)&"_"&LEFT(F17,4)&"_"&LEFT(G17,5)&"_"&LEFT(H17,5) -> J32_M32_4370_Z3703_63202 | K17: =LEFT(H17,10) -> 63202-1000 | L17: =IFERROR(VLOOKUP($J17,[2]OPEX!$H:$AM,L$2,FALSE),"-") -> Sport Dep | M17: =IFERROR(VLOOKUP($J17,[2]OPEX!$H:$AM,M$2,FALSE),"-") -> C+Sport | N17: =IFERROR(VLOOKUP($J17,[2]OPEX!$H:$AM,N$2,FALSE),"-") -> Liga+ | O17: =IFERROR(VLOOKUP($J17,[2]OPEX!$H:$AM,O$2,FALSE),"-") -> Pprod-Editing | P17: =IFERROR(VLOOKUP($J17,[2]OPEX!$H:$AM,P$2,FALSE),"-") -> PS1S0M0IL3 | Q17: =IFERROR(VLOOKUP($J17,[2]OPEX!$H:$AM,Q$2,FALSE),"-") -> C+Sport Mag Liga+ Postprod | R17: =S17 -> PRODUKCJA – MONTAŻ/WIDEO/MIKS/AUDIO | S17: =IFERROR(VLOOKUP($J17,[2]OPEX!$H:$AM,S$2,FALSE),"-") -> PRODUKCJA – MONTAŻ/WIDEO/MIKS/AUDIO | T17: =IFERROR(VLOOKUP($J17,[2]OPEX!$H:$AM,T$2,FALSE),"-") | U17: =IFERROR(VLOOKUP($J17,[2]OPEX!$H:$AM,U$2,FALSE),"-") | V17: =IFERROR(VLOOKUP($J17,[2]OPEX!$H:$AM,V$2,FALSE),"-") | W17: =IFERROR(VLOOKUP($J17,[2]OPEX!$H:$AM,W$2,FALSE),"-") | X17: =IFERROR(VLOOKUP($J17,[2]OPEX!$H:$AM,X$2,FALSE),"-") | Y17: =IFERROR(VLOOKUP($J17,[2]OPEX!$H:$AM,Y$2,FALSE),"-") | Z17: =IFERROR(VLOOKUP($J17,[2]OPEX!$H:$AM,Z$2,FALSE),"-") | ... AD17: =IFERROR(VLOOKUP($J17,[2]OPEX!$H:$AM,AD$2,FALSE),"-") | AF17: =VLOOKUP(J17,[3]BU_COSTS!$C:$C,1,FALSE) -> J32_M32_4370_Z3703_63202
A18: Liga+Extra | B18: 5010000 D02 K13 RK528 AN00207 | C18: 5010000_D02_K13_RK528_AN00207 | D18: J32_CANAL+ SPORT | E18: M32_CANAL+ SPORT | F18: 4370_MAGAZINES | G18: Z3702_LIGA+ EXTRA | H18: 63202-1000_Koszty redakcji - umowy cywilno-prawne | I18: =LEFT(D18,3)&"_"&LEFT(E18,3)&"_"&LEFT(F18,4)&"_"&LEFT(G18,5)&"_"&LEFT(H18,10) -> J32_M32_4370_Z3702_63202-1000 | J18: =LEFT(D18,3)&"_"&LEFT(E18,3)&"_"&LEFT(F18,4)&"_"&LEFT(G18,5)&"_"&LEFT(H18,5) -> J32_M32_4370_Z3702_63202 | K18: =LEFT(H18,10) -> 63202-1000 | L18: =IFERROR(VLOOKUP($J18,[2]OPEX!$H:$AM,L$2,FALSE),"-") -> Sport Dep | M18: =IFERROR(VLOOKUP($J18,[2]OPEX!$H:$AM,M$2,FALSE),"-") -> C+Sport | N18: =IFERROR(VLOOKUP($J18,[2]OPEX!$H:$AM,N$2,FALSE),"-") -> L+Extra | O18: =IFERROR(VLOOKUP($J18,[2]OPEX!$H:$AM,O$2,FALSE),"-") -> Pprod-Editing | P18: =IFERROR(VLOOKUP($J18,[2]OPEX!$H:$AM,P$2,FALSE),"-") -> PS1S0M0JK3 | Q18: =IFERROR(VLOOKUP($J18,[2]OPEX!$H:$AM,Q$2,FALSE),"-") -> C+Sport Mag L+Extra Postprod | R18: =S18 -> PRODUKCJA – MONTAŻ/WIDEO/MIKS/AUDIO | S18: =IFERROR(VLOOKUP($J18,[2]OPEX!$H:$AM,S$2,FALSE),"-") -> PRODUKCJA – MONTAŻ/WIDEO/MIKS/AUDIO | T18: =IFERROR(VLOOKUP($J18,[2]OPEX!$H:$AM,T$2,FALSE),"-") | U18: =IFERROR(VLOOKUP($J18,[2]OPEX!$H:$AM,U$2,FALSE),"-") | V18: =IFERROR(VLOOKUP($J18,[2]OPEX!$H:$AM,V$2,FALSE),"-") | W18: =IFERROR(VLOOKUP($J18,[2]OPEX!$H:$AM,W$2,FALSE),"-") | X18: =IFERROR(VLOOKUP($J18,[2]OPEX!$H:$AM,X$2,FALSE),"-") | Y18: =IFERROR(VLOOKUP($J18,[2]OPEX!$H:$AM,Y$2,FALSE),"-") | Z18: =IFERROR(VLOOKUP($J18,[2]OPEX!$H:$AM,Z$2,FALSE),"-") | ... AD18: =IFERROR(VLOOKUP($J18,[2]OPEX!$H:$AM,AD$2,FALSE),"-") | AF18: =VLOOKUP(J18,[3]BU_COSTS!$C:$C,1,FALSE) -> J32_M32_4370_Z3702_63202
A19: Magazyn 1 Ligi zużlowej | B19: 5010000 D02 K13 RK535 AN00207 | C19: 5010000_D02_K13_RK535_AN00207 | D19: J32_CANAL+ SPORT | E19: M32_CANAL+ SPORT | F19: 4370_MAGAZINES | G19: Z3724_Magazyn 1 Ligi | H19: 63202-1000_Koszty redakcji - umowy cywilno-prawne | I19: =LEFT(D19,3)&"_"&LEFT(E19,3)&"_"&LEFT(F19,4)&"_"&LEFT(G19,5)&"_"&LEFT(H19,10) -> J32_M32_4370_Z3724_63202-1000 | J19: =LEFT(D19,3)&"_"&LEFT(E19,3)&"_"&LEFT(F19,4)&"_"&LEFT(G19,5)&"_"&LEFT(H19,5) -> J32_M32_4370_Z3724_63202 | K19: =LEFT(H19,10) -> 63202-1000 | L19: =IFERROR(VLOOKUP($J19,[2]OPEX!$H:$AM,L$2,FALSE),"-") -> Sport Dep | M19: =IFERROR(VLOOKUP($J19,[2]OPEX!$H:$AM,M$2,FALSE),"-") -> C+Sport | N19: =IFERROR(VLOOKUP($J19,[2]OPEX!$H:$AM,N$2,FALSE),"-") -> Mag Speed 2M Ekstraliga | O19: =IFERROR(VLOOKUP($J19,[2]OPEX!$H:$AM,O$2,FALSE),"-") -> Pprod-Editing | P19: =IFERROR(VLOOKUP($J19,[2]OPEX!$H:$AM,P$2,FALSE),"-") -> PS1S0M0KE3 | Q19: =IFERROR(VLOOKUP($J19,[2]OPEX!$H:$AM,Q$2,FALSE),"-") -> C+Sport Mag Speedway 2M Ekstral Postprod | R19: =S19 -> PRODUKCJA – MONTAŻ/WIDEO/MIKS/AUDIO | S19: =IFERROR(VLOOKUP($J19,[2]OPEX!$H:$AM,S$2,FALSE),"-") -> PRODUKCJA – MONTAŻ/WIDEO/MIKS/AUDIO | T19: =IFERROR(VLOOKUP($J19,[2]OPEX!$H:$AM,T$2,FALSE),"-") | U19: =IFERROR(VLOOKUP($J19,[2]OPEX!$H:$AM,U$2,FALSE),"-") | V19: =IFERROR(VLOOKUP($J19,[2]OPEX!$H:$AM,V$2,FALSE),"-") | W19: =IFERROR(VLOOKUP($J19,[2]OPEX!$H:$AM,W$2,FALSE),"-") | X19: =IFERROR(VLOOKUP($J19,[2]OPEX!$H:$AM,X$2,FALSE),"-") | Y19: =IFERROR(VLOOKUP($J19,[2]OPEX!$H:$AM,Y$2,FALSE),"-") | Z19: =IFERROR(VLOOKUP($J19,[2]OPEX!$H:$AM,Z$2,FALSE),"-") | ... AD19: =IFERROR(VLOOKUP($J19,[2]OPEX!$H:$AM,AD$2,FALSE),"-") | AF19: =VLOOKUP(J19,[3]BU_COSTS!$C:$C,1,FALSE) -> J32_M32_4370_Z3724_63202
A20: Magazyn Hola La Liga | B20: 5010000 D02 K13 RK641 AN00207 | C20: 5010000_D02_K13_RK641_AN00207 | D20: J32_CANAL+ SPORT | E20: M32_CANAL+ SPORT | F20: 4370_MAGAZINES | G20: Z3706_HOLA LA LIGA | H20: 63202-1000_Koszty redakcji - umowy cywilno-prawne | I20: =LEFT(D20,3)&"_"&LEFT(E20,3)&"_"&LEFT(F20,4)&"_"&LEFT(G20,5)&"_"&LEFT(H20,10) -> J32_M32_4370_Z3706_63202-1000 | J20: =LEFT(D20,3)&"_"&LEFT(E20,3)&"_"&LEFT(F20,4)&"_"&LEFT(G20,5)&"_"&LEFT(H20,5) -> J32_M32_4370_Z3706_63202 | K20: =LEFT(H20,10) -> 63202-1000 | L20: =IFERROR(VLOOKUP($J20,[2]OPEX!$H:$AM,L$2,FALSE),"-") -> Sport Dep | M20: =IFERROR(VLOOKUP($J20,[2]OPEX!$H:$AM,M$2,FALSE),"-") -> C+Sport | N20: =IFERROR(VLOOKUP($J20,[2]OPEX!$H:$AM,N$2,FALSE),"-") -> Old Magazines | O20: =IFERROR(VLOOKUP($J20,[2]OPEX!$H:$AM,O$2,FALSE),"-") -> Pprod-Editing | P20: =IFERROR(VLOOKUP($J20,[2]OPEX!$H:$AM,P$2,FALSE),"-") -> PS1S0M0G13 | Q20: =IFERROR(VLOOKUP($J20,[2]OPEX!$H:$AM,Q$2,FALSE),"-") -> C+Sport Maga Old Postprod | R20: =S20 | S20: =IFERROR(VLOOKUP($J20,[2]OPEX!$H:$AM,S$2,FALSE),"-") | T20: =IFERROR(VLOOKUP($J20,[2]OPEX!$H:$AM,T$2,FALSE),"-") | U20: =IFERROR(VLOOKUP($J20,[2]OPEX!$H:$AM,U$2,FALSE),"-") | V20: =IFERROR(VLOOKUP($J20,[2]OPEX!$H:$AM,V$2,FALSE),"-") | W20: =IFERROR(VLOOKUP($J20,[2]OPEX!$H:$AM,W$2,FALSE),"-") | X20: =IFERROR(VLOOKUP($J20,[2]OPEX!$H:$AM,X$2,FALSE),"-") | Y20: =IFERROR(VLOOKUP($J20,[2]OPEX!$H:$AM,Y$2,FALSE),"-") | Z20: =IFERROR(VLOOKUP($J20,[2]OPEX!$H:$AM,Z$2,FALSE),"-") | ... AD20: =IFERROR(VLOOKUP($J20,[2]OPEX!$H:$AM,AD$2,FALSE),"-") | AF20: =VLOOKUP(J20,[3]BU_COSTS!$C:$C,1,FALSE) -> J32_M32_4370_Z3706_63202
A21: Magazyn LALIGA (Kroniki; World; Show) | D21: J32_CANAL+ SPORT | E21: M32_CANAL+ SPORT | F21: 4370_MAGAZINES | G21: Z3710_SPORT+ | H21: 63202-1000_Koszty redakcji - umowy cywilno-prawne | I21: =LEFT(D21,3)&"_"&LEFT(E21,3)&"_"&LEFT(F21,4)&"_"&LEFT(G21,5)&"_"&LEFT(H21,10) -> J32_M32_4370_Z3710_63202-1000 | J21: =LEFT(D21,3)&"_"&LEFT(E21,3)&"_"&LEFT(F21,4)&"_"&LEFT(G21,5)&"_"&LEFT(H21,5) -> J32_M32_4370_Z3710_63202 | K21: =LEFT(H21,10) -> 63202-1000 | L21: =IFERROR(VLOOKUP($J21,[2]OPEX!$H:$AM,L$2,FALSE),"-") -> Sport Dep | M21: =IFERROR(VLOOKUP($J21,[2]OPEX!$H:$AM,M$2,FALSE),"-") -> C+Sport | N21: =IFERROR(VLOOKUP($J21,[2]OPEX!$H:$AM,N$2,FALSE),"-") -> Sport+ | O21: =IFERROR(VLOOKUP($J21,[2]OPEX!$H:$AM,O$2,FALSE),"-") -> Pprod-Editing | P21: =IFERROR(VLOOKUP($J21,[2]OPEX!$H:$AM,P$2,FALSE),"-") -> PS1S0M0RP3 | Q21: =IFERROR(VLOOKUP($J21,[2]OPEX!$H:$AM,Q$2,FALSE),"-") -> C+Sport Mag Sport+ Postprod | R21: =S21 -> PRODUKCJA – MONTAŻ/WIDEO/MIKS/AUDIO | S21: =IFERROR(VLOOKUP($J21,[2]OPEX!$H:$AM,S$2,FALSE),"-") -> PRODUKCJA – MONTAŻ/WIDEO/MIKS/AUDIO | T21: =IFERROR(VLOOKUP($J21,[2]OPEX!$H:$AM,T$2,FALSE),"-") | U21: =IFERROR(VLOOKUP($J21,[2]OPEX!$H:$AM,U$2,FALSE),"-") | V21: =IFERROR(VLOOKUP($J21,[2]OPEX!$H:$AM,V$2,FALSE),"-") | W21: =IFERROR(VLOOKUP($J21,[2]OPEX!$H:$AM,W$2,FALSE),"-") | X21: =IFERROR(VLOOKUP($J21,[2]OPEX!$H:$AM,X$2,FALSE),"-") | Y21: =IFERROR(VLOOKUP($J21,[2]OPEX!$H:$AM,Y$2,FALSE),"-") | Z21: =IFERROR(VLOOKUP($J21,[2]OPEX!$H:$AM,Z$2,FALSE),"-") | ... AD21: =IFERROR(VLOOKUP($J21,[2]OPEX!$H:$AM,AD$2,FALSE),"-") | AF21: =VLOOKUP(J21,[3]BU_COSTS!$C:$C,1,FALSE) -> J32_M32_4370_Z3710_63202
A22: Magazyn Lig Zagranicznych | B22: BRAK | C22: 5010000_D02_K13_RK508_AN00207 | D22: J32_CANAL+ SPORT | E22: M32_CANAL+ SPORT | F22: 4370_MAGAZINES | G22: Z3704_MAGAZYN LIG ZAGRANICZNYCH | H22: 63202-1000_Koszty redakcji - umowy cywilno-prawne | I22: =LEFT(D22,3)&"_"&LEFT(E22,3)&"_"&LEFT(F22,4)&"_"&LEFT(G22,5)&"_"&LEFT(H22,10) -> J32_M32_4370_Z3704_63202-1000 | J22: =LEFT(D22,3)&"_"&LEFT(E22,3)&"_"&LEFT(F22,4)&"_"&LEFT(G22,5)&"_"&LEFT(H22,5) -> J32_M32_4370_Z3704_63202 | K22: =LEFT(H22,10) -> 63202-1000 | L22: =IFERROR(VLOOKUP($J22,[2]OPEX!$H:$AM,L$2,FALSE),"-") -> Sport Dep | M22: =IFERROR(VLOOKUP($J22,[2]OPEX!$H:$AM,M$2,FALSE),"-") -> C+Sport | N22: =IFERROR(VLOOKUP($J22,[2]OPEX!$H:$AM,N$2,FALSE),"-") -> Mag Lig Zagranicznych | O22: =IFERROR(VLOOKUP($J22,[2]OPEX!$H:$AM,O$2,FALSE),"-") -> Pprod-Editing | P22: =IFERROR(VLOOKUP($J22,[2]OPEX!$H:$AM,P$2,FALSE),"-") -> PS1S0M0MZ3 | Q22: =IFERROR(VLOOKUP($J22,[2]OPEX!$H:$AM,Q$2,FALSE),"-") -> C+Sport Mag Lig Zagr Postprod | R22: =S22 -> PRODUKCJA – MONTAŻ/WIDEO/MIKS/AUDIO | S22: =IFERROR(VLOOKUP($J22,[2]OPEX!$H:$AM,S$2,FALSE),"-") -> PRODUKCJA – MONTAŻ/WIDEO/MIKS/AUDIO | T22: =IFERROR(VLOOKUP($J22,[2]OPEX!$H:$AM,T$2,FALSE),"-") | U22: =IFERROR(VLOOKUP($J22,[2]OPEX!$H:$AM,U$2,FALSE),"-") | V22: =IFERROR(VLOOKUP($J22,[2]OPEX!$H:$AM,V$2,FALSE),"-") | W22: =IFERROR(VLOOKUP($J22,[2]OPEX!$H:$AM,W$2,FALSE),"-") | X22: =IFERROR(VLOOKUP($J22,[2]OPEX!$H:$AM,X$2,FALSE),"-") | Y22: =IFERROR(VLOOKUP($J22,[2]OPEX!$H:$AM,Y$2,FALSE),"-") | Z22: =IFERROR(VLOOKUP($J22,[2]OPEX!$H:$AM,Z$2,FALSE),"-") | ... AD22: =IFERROR(VLOOKUP($J22,[2]OPEX!$H:$AM,AD$2,FALSE),"-") | AF22: =VLOOKUP(J22,[3]BU_COSTS!$C:$C,1,FALSE) -> J32_M32_4370_Z3704_63202
A23: Magazyn PGE Ekstraligi | B23: 5010000 D02 K13 RK515 AN00207 | C23: 5010000_D02_K13_RK515_AN00207 | D23: J32_CANAL+ SPORT | E23: M32_CANAL+ SPORT | F23: 4370_MAGAZINES | G23: Z3721_MAGAZYN ENEA EKSTRALIGI | H23: 63202-1000_Koszty redakcji - umowy cywilno-prawne | I23: =LEFT(D23,3)&"_"&LEFT(E23,3)&"_"&LEFT(F23,4)&"_"&LEFT(G23,5)&"_"&LEFT(H23,10) -> J32_M32_4370_Z3721_63202-1000 | J23: =LEFT(D23,3)&"_"&LEFT(E23,3)&"_"&LEFT(F23,4)&"_"&LEFT(G23,5)&"_"&LEFT(H23,5) -> J32_M32_4370_Z3721_63202 | K23: =LEFT(H23,10) -> 63202-1000 | L23: =IFERROR(VLOOKUP($J23,[2]OPEX!$H:$AM,L$2,FALSE),"-") -> Sport Dep | M23: =IFERROR(VLOOKUP($J23,[2]OPEX!$H:$AM,M$2,FALSE),"-") -> C+Sport | N23: =IFERROR(VLOOKUP($J23,[2]OPEX!$H:$AM,N$2,FALSE),"-") -> Mag Speed Ekstraliga | O23: =IFERROR(VLOOKUP($J23,[2]OPEX!$H:$AM,O$2,FALSE),"-") -> Pprod-Editing | P23: =IFERROR(VLOOKUP($J23,[2]OPEX!$H:$AM,P$2,FALSE),"-") -> PS1S0M0LL3 | Q23: =IFERROR(VLOOKUP($J23,[2]OPEX!$H:$AM,Q$2,FALSE),"-") -> C+Sport Mag Speedway Ekstraligi Postprod | R23: =S23 -> PRODUKCJA – MONTAŻ/WIDEO/MIKS/AUDIO | S23: =IFERROR(VLOOKUP($J23,[2]OPEX!$H:$AM,S$2,FALSE),"-") -> PRODUKCJA – MONTAŻ/WIDEO/MIKS/AUDIO | T23: =IFERROR(VLOOKUP($J23,[2]OPEX!$H:$AM,T$2,FALSE),"-") | U23: =IFERROR(VLOOKUP($J23,[2]OPEX!$H:$AM,U$2,FALSE),"-") | V23: =IFERROR(VLOOKUP($J23,[2]OPEX!$H:$AM,V$2,FALSE),"-") | W23: =IFERROR(VLOOKUP($J23,[2]OPEX!$H:$AM,W$2,FALSE),"-") | X23: =IFERROR(VLOOKUP($J23,[2]OPEX!$H:$AM,X$2,FALSE),"-") | Y23: =IFERROR(VLOOKUP($J23,[2]OPEX!$H:$AM,Y$2,FALSE),"-") | Z23: =IFERROR(VLOOKUP($J23,[2]OPEX!$H:$AM,Z$2,FALSE),"-") | ... AD23: =IFERROR(VLOOKUP($J23,[2]OPEX!$H:$AM,AD$2,FALSE),"-") | AF23: =VLOOKUP(J23,[3]BU_COSTS!$C:$C,1,FALSE) -> J32_M32_4370_Z3721_63202
A24: Odprawa Przedmeczowa | D24: J32_CANAL+ SPORT | E24: M32_CANAL+ SPORT | F24: 4370_MAGAZINES | G24: Z3713_ON LINE | H24: 63202-1000_Koszty redakcji - umowy cywilno-prawne | I24: =LEFT(D24,3)&"_"&LEFT(E24,3)&"_"&LEFT(F24,4)&"_"&LEFT(G24,5)&"_"&LEFT(H24,10) -> J32_M32_4370_Z3713_63202-1000 | J24: =LEFT(D24,3)&"_"&LEFT(E24,3)&"_"&LEFT(F24,4)&"_"&LEFT(G24,5)&"_"&LEFT(H24,5) -> J32_M32_4370_Z3713_63202 | K24: =LEFT(H24,10) -> 63202-1000 | L24: =IFERROR(VLOOKUP($J24,[2]OPEX!$H:$AM,L$2,FALSE),"-") -> Sport Dep | M24: =IFERROR(VLOOKUP($J24,[2]OPEX!$H:$AM,M$2,FALSE),"-") -> C+Sport | N24: =IFERROR(VLOOKUP($J24,[2]OPEX!$H:$AM,N$2,FALSE),"-") -> Digital media | O24: =IFERROR(VLOOKUP($J24,[2]OPEX!$H:$AM,O$2,FALSE),"-") -> Pprod-Editing | P24: =IFERROR(VLOOKUP($J24,[2]OPEX!$H:$AM,P$2,FALSE),"-") -> PS1S0M0NG3 | Q24: =IFERROR(VLOOKUP($J24,[2]OPEX!$H:$AM,Q$2,FALSE),"-") -> C+Sport Mag Digital Postprod | R24: =S24 -> PRODUKCJA – MONTAŻ/WIDEO/MIKS/AUDIO | S24: =IFERROR(VLOOKUP($J24,[2]OPEX!$H:$AM,S$2,FALSE),"-") -> PRODUKCJA – MONTAŻ/WIDEO/MIKS/AUDIO | T24: =IFERROR(VLOOKUP($J24,[2]OPEX!$H:$AM,T$2,FALSE),"-") | U24: =IFERROR(VLOOKUP($J24,[2]OPEX!$H:$AM,U$2,FALSE),"-") | V24: =IFERROR(VLOOKUP($J24,[2]OPEX!$H:$AM,V$2,FALSE),"-") | W24: =IFERROR(VLOOKUP($J24,[2]OPEX!$H:$AM,W$2,FALSE),"-") | X24: =IFERROR(VLOOKUP($J24,[2]OPEX!$H:$AM,X$2,FALSE),"-") | Y24: =IFERROR(VLOOKUP($J24,[2]OPEX!$H:$AM,Y$2,FALSE),"-") | Z24: =IFERROR(VLOOKUP($J24,[2]OPEX!$H:$AM,Z$2,FALSE),"-") | ... AD24: =IFERROR(VLOOKUP($J24,[2]OPEX!$H:$AM,AD$2,FALSE),"-") | AF24: =VLOOKUP(J24,[3]BU_COSTS!$C:$C,1,FALSE) -> J32_M32_4370_Z3713_63202
A25: Padel | D25: J32_CANAL+ SPORT | E25: M32_CANAL+ SPORT | F25: 4369_OTHER SPORTS | G25: Z3696_EVENTS-SPORT POZOSTAŁE | H25: 63202-1000_Koszty redakcji - umowy cywilno-prawne | I25: =LEFT(D25,3)&"_"&LEFT(E25,3)&"_"&LEFT(F25,4)&"_"&LEFT(G25,5)&"_"&LEFT(H25,10) -> J32_M32_4369_Z3696_63202-1000 | J25: =LEFT(D25,3)&"_"&LEFT(E25,3)&"_"&LEFT(F25,4)&"_"&LEFT(G25,5)&"_"&LEFT(H25,5) -> J32_M32_4369_Z3696_63202 | K25: =LEFT(H25,10) -> 63202-1000 | L25: =IFERROR(VLOOKUP($J25,[2]OPEX!$H:$AM,L$2,FALSE),"-") -> Sport Dep | M25: =IFERROR(VLOOKUP($J25,[2]OPEX!$H:$AM,M$2,FALSE),"-") -> C+Sport | N25: =IFERROR(VLOOKUP($J25,[2]OPEX!$H:$AM,N$2,FALSE),"-") -> Other sport events | O25: =IFERROR(VLOOKUP($J25,[2]OPEX!$H:$AM,O$2,FALSE),"-") -> Pprod-Editing | P25: =IFERROR(VLOOKUP($J25,[2]OPEX!$H:$AM,P$2,FALSE),"-") -> PS1S0M10V3 | Q25: =IFERROR(VLOOKUP($J25,[2]OPEX!$H:$AM,Q$2,FALSE),"-") -> C+Sport Other Sports events Postprod | R25: =S25 -> PRODUKCJA – MONTAŻ/WIDEO/MIKS/AUDIO | S25: =IFERROR(VLOOKUP($J25,[2]OPEX!$H:$AM,S$2,FALSE),"-") -> PRODUKCJA – MONTAŻ/WIDEO/MIKS/AUDIO | T25: =IFERROR(VLOOKUP($J25,[2]OPEX!$H:$AM,T$2,FALSE),"-") | U25: =IFERROR(VLOOKUP($J25,[2]OPEX!$H:$AM,U$2,FALSE),"-") | V25: =IFERROR(VLOOKUP($J25,[2]OPEX!$H:$AM,V$2,FALSE),"-") | W25: =IFERROR(VLOOKUP($J25,[2]OPEX!$H:$AM,W$2,FALSE),"-") | X25: =IFERROR(VLOOKUP($J25,[2]OPEX!$H:$AM,X$2,FALSE),"-") | Y25: =IFERROR(VLOOKUP($J25,[2]OPEX!$H:$AM,Y$2,FALSE),"-") | Z25: =IFERROR(VLOOKUP($J25,[2]OPEX!$H:$AM,Z$2,FALSE),"-") | ... AD25: =IFERROR(VLOOKUP($J25,[2]OPEX!$H:$AM,AD$2,FALSE),"-") | AF25: =VLOOKUP(J25,[3]BU_COSTS!$C:$C,1,FALSE) -> J32_M32_4369_Z3696_63202
A26: Padel HOLANDIA | D26: J22_TV TECHNOLOGY | E26: M02_EXTERNAL MARKETS | F26: 4377_M7_PLAYOUT_LIVE | G26: Z9174_M7_NETHERLANDS | H26: 63202-1000_Koszty redakcji - umowy cywilno-prawne | I26: =LEFT(D26,3)&"_"&LEFT(E26,3)&"_"&LEFT(F26,4)&"_"&LEFT(G26,5)&"_"&LEFT(H26,10) -> J22_M02_4377_Z9174_63202-1000 | J26: =LEFT(D26,3)&"_"&LEFT(E26,3)&"_"&LEFT(F26,4)&"_"&LEFT(G26,5)&"_"&LEFT(H26,5) -> J22_M02_4377_Z9174_63202 | K26: =LEFT(H26,10) -> 63202-1000 | L26: Headend&MAM Dep | M26: Group Services | N26: M7/ACTION/NL | O26: Production | P26: PT2X0XANS3 | Q26: M7 NL PRODUCTION COST E | R26: PRACOWNICY TYMCZASOWI | S26: PRACOWNICY TYMCZASOWI | T26: USŁUGI PRODUKCYJNE ZEWNĘTRZNE | U26: =IFERROR(VLOOKUP($J26,[2]OPEX!$H:$AM,U$2,FALSE),"-") -> - | V26: =IFERROR(VLOOKUP($J26,[2]OPEX!$H:$AM,V$2,FALSE),"-") -> - | W26: =IFERROR(VLOOKUP($J26,[2]OPEX!$H:$AM,W$2,FALSE),"-") -> - | X26: =IFERROR(VLOOKUP($J26,[2]OPEX!$H:$AM,X$2,FALSE),"-") -> - | Y26: =IFERROR(VLOOKUP($J26,[2]OPEX!$H:$AM,Y$2,FALSE),"-") -> - | Z26: =IFERROR(VLOOKUP($J26,[2]OPEX!$H:$AM,Z$2,FALSE),"-") -> - | AA26: =IFERROR(VLOOKUP($J26,[2]OPEX!$H:$AM,AA$2,FALSE),"-") -> - | AB26: =IFERROR(VLOOKUP($J26,[2]OPEX!$H:$AM,AB$2,FALSE),"-") -> - | ... AD26: =IFERROR(VLOOKUP($J26,[2]OPEX!$H:$AM,AD$2,FALSE),"-") -> - | AF26: =VLOOKUP(J26,[3]BU_COSTS!$C:$C,1,FALSE) -> #N/A
